Workbook

Sheet 2026年10月 
A1: 46296 | C1: １年 | E1: ２年 | G1: ３年 | I1: ４年 | K1: 助産 | M1: 研究課程部 Ｍ１ | O1: 研究課程部 Ｍ２ | Q1: 研究課程部 Ｄ１ | S1: 研究課程部 Ｄ２３ | U1: =A1 -> 46296 | V1: 授業外その他教室等管理スケジュール | AA1: １階 | AG1: ２階 | AW1: ３階 | BI1: ４階 | BN1: 体育棟 | BP1: 研修棟
C2: =A1 -> 46296 | U2: =C2 -> 46296 | AA2: 101 | AB2: 102 | AC2: 103 | AD2: 在宅実習室 | AE2: 成人実習室 | AF2: 講堂 | AG2: 201 | AH2: 202 | AI2: 203 | AJ2: 204 | AK2: 205 | AL2: 基礎実習室 | AM2: 母性・小児実習室 | AN2: 演習21 | AO2: 演習22 | AP2: 演習23 | AQ2: 演習24 | AR2: 演習25 | AS2: 演習26 | AT2: 演習27 | AU2: 演習28 | AV2: 演習29 | AW2: 301 | AX2: 302 | AY2: 303 | AZ2: 304 | BA2: 臨床１ | BB2: 臨床２ | BC2: LL1 | BD2: LL2 | BE2: 実験室 | BF2: 情報処理室 | BG2: 演習31 | BH2: 演習32 | BI2: セミナー室１ | BJ2: セミナー室２ | BK2: セミナー室3 | BL2: セミナー室4 | BM2: セミナー室5 | BN2: 大講義室 | BO2: アリーナ | BP2: 研修１ | BQ2: 研修３ | BR2: 研修４ | BS2: 研修５ | BT2: 研修６ | BU2: 研修７ | BV2: 視聴覚室
A3: １時限（09：20～10：50） | B3: 科目名 | C3: =VLOOKUP($C2,'2026年度(1年後期)'!$B$5:$N$207,COLUMN('2026年度(1年後期)'!$C$5),0)&"" -> 教科書販売 | E3: =VLOOKUP($C2,'2026年度(2年後期)'!$B$5:$N$207,COLUMN('2026年度(2年後期)'!$C$5),0)&"" -> 教科書販売 | G3: =VLOOKUP($C2,'2026年度(3年後期)'!$B$5:$N$207,COLUMN('2026年度(3年後期)'!$C$5),0)&"" -> 領域別実習 | I3: =VLOOKUP($C2,'2026年度(4年後期)'!$B$5:$N$206,COLUMN('2026年度(4年後期)'!$C$5),0)&"" -> 教科書販売 | K3: =VLOOKUP($C2,'2026年度(助産後期)'!$B$5:$N$207,COLUMN('2026年度(助産後期)'!$C$5),0)&"" -> 助産学実習Ⅰ | M3: =VLOOKUP($C2,'2026年度(M1後期)'!$B$5:$N$207,COLUMN('2026年度(M1後期)'!$C$5),0)&"" -> がん看護学演習A-Ⅰ 感染症学特論 感染症学演習 | O3: =VLOOKUP($C2,'2026年度(M2後期)'!$B$5:$N$207,COLUMN('2026年度(M2後期)'!$C$5),0)&"" -> 特別研究 | Q3: =VLOOKUP($C2,'2026年度(D1後期)'!$B$5:$N$207,COLUMN('2026年度(D1後期)'!$C$5),0)&"" -> 看護情報・管理学演習Ｂ 長寿看護学演習Ｂ | S3: =VLOOKUP($C2,'2026年度(D23後期)'!$B$5:$N$207,COLUMN('2026年度(D23後期)'!$C$5),0)&"" -> 特別研究 | U3: 1,2限 | V3: 1限 | W3: 1限 | Y3: １限 | Z3: =A3 -> １時限（09：20～10：50） | AY3: 卒業研究（老年） | BD3: 日當 | BI3: D3坂口 | BM3: M1國分
B4: 教 官 | C4: =IFERROR(VLOOKUP(C3,科目・教員!$A$2:$B$342,2,0),"") | E4: =IFERROR(VLOOKUP(E3,科目・教員!$A$2:$B$342,2,0),"") | G4: =IFERROR(VLOOKUP(G3,科目・教員!$A$2:$B$342,2,0),"") | I4: =IFERROR(VLOOKUP(I3,科目・教員!$A$2:$B$342,2,0),"") | K4: =IFERROR(VLOOKUP(K3,科目・教員!$A$2:$B$342,2,0),"") -> 池田 真弓 | M4: =IFERROR(VLOOKUP(M3,科目・教員!$A$2:$B$342,2,0),"") | O4: =IFERROR(VLOOKUP(O3,科目・教員!$A$2:$B$342,2,0),"") | Q4: =IFERROR(VLOOKUP(Q3,科目・教員!$A$2:$B$342,2,0),"") | S4: =IFERROR(VLOOKUP(S3,科目・教員!$A$2:$B$342,2,0),"") | U4: 会議参加 | V4: 卒業研究（老年） | W4: ゼミ | Y4: 精神看護学
B5: 使用教室 | C5: =VLOOKUP($C2,'2026年度(1年後期)'!$B$5:$N$207,COLUMN('2026年度(1年後期)'!$C$5)+1,0)&"" -> 講堂前ロビー | E5: =VLOOKUP($C2,'2026年度(2年後期)'!$B$5:$N$207,COLUMN('2026年度(2年後期)'!$C$5)+1,0)&"" -> 講堂前ロビー | G5: =VLOOKUP($C2,'2026年度(3年後期)'!$B$5:$N$207,COLUMN('2026年度(3年後期)'!$C$5)+1,0)&"" | I5: =VLOOKUP($C2,'2026年度(4年後期)'!$B$5:$N$206,COLUMN('2026年度(4年後期)'!$C$5)+1,0)&"" -> 講堂前ロビー | K5: =VLOOKUP($C2,'2026年度(助産後期)'!$B$5:$N$207,COLUMN('2026年度(助産後期)'!$C$5)+1,0)&"" | M5: =VLOOKUP($C2,'2026年度(M1後期)'!$B$5:$N$207,COLUMN('2026年度(M1後期)'!$C$5)+1,0)&"" | O5: =VLOOKUP($C2,'2026年度(M2後期)'!$B$5:$N$207,COLUMN('2026年度(M2後期)'!$C$5)+1,0)&"" | Q5: =VLOOKUP($C2,'2026年度(D1後期)'!$B$5:$N$207,COLUMN('2026年度(D1後期)'!$C$5)+1,0)&"" | S5: =VLOOKUP($C2,'2026年度(D23後期)'!$B$5:$N$207,COLUMN('2026年度(D23後期)'!$C$5)+1,0)&"" | U5: 研究業務係日當 | V5: 松岡先生 | W5: D3坂口 | Y5: M1國分
B6: 備 考 | U6: LL2 | V6: 303教室 | W6: セミナールーム1 | Y6: セミナールーム５
A7: ２時限（11：00～12：30） | B7: 科目名 | C7: =VLOOKUP($C2,'2026年度(1年後期)'!$B$5:$N$207,COLUMN('2026年度(1年後期)'!$E$5),0)&"" -> 後期授業ガイダンス | E7: =VLOOKUP($C2,'2026年度(2年後期)'!$B$5:$N$207,COLUMN('2026年度(2年後期)'!$E$5),0)&"" -> 後期授業ガイダンス | G7: =VLOOKUP($C2,'2026年度(3年後期)'!$B$5:$N$207,COLUMN('2026年度(3年後期)'!$E$5),0)&"" -> 領域別実習 | I7: =VLOOKUP($C2,'2026年度(4年後期)'!$B$5:$N$206,COLUMN('2026年度(4年後期)'!$E$5),0)&"" -> 後期授業ガイダンス | K7: =VLOOKUP($C2,'2026年度(助産後期)'!$B$5:$N$207,COLUMN('2026年度(助産後期)'!$E$5),0)&"" -> 助産学実習Ⅰ | M7: =VLOOKUP($C2,'2026年度(M1後期)'!$B$5:$N$207,COLUMN('2026年度(M1後期)'!$E$5),0)&"" -> がん看護学演習A-Ⅰ 感染症学特論 感染症学演習 | O7: =VLOOKUP($C2,'2026年度(M2後期)'!$B$5:$N$207,COLUMN('2026年度(M2後期)'!$E$5),0)&"" -> 特別研究 | Q7: =VLOOKUP($C2,'2026年度(D1後期)'!$B$5:$N$207,COLUMN('2026年度(D1後期)'!$E$5),0)&"" -> 看護情報・管理学演習Ｂ 長寿看護学演習Ｂ | S7: =VLOOKUP($C2,'2026年度(D23後期)'!$B$5:$N$207,COLUMN('2026年度(D23後期)'!$E$5),0)&"" -> 特別研究 | U7: １１：００～１２：３０ | Z7: =A7 -> ２時限（11：00～12：30） | AA7: 後期授業ガイダンス | AG7: 後期授業ガイダンス | AW7: 後期授業ガイダンス | BD7: 日當 | BI7: M2尾澤
B8: 教 官 | C8: =IFERROR(VLOOKUP(C7,科目・教員!$A$2:$B$342,2,0),"") | E8: =IFERROR(VLOOKUP(E7,科目・教員!$A$2:$B$342,2,0),"") | G8: =IFERROR(VLOOKUP(G7,科目・教員!$A$2:$B$342,2,0),"") | I8: =IFERROR(VLOOKUP(I7,科目・教員!$A$2:$B$342,2,0),"") | K8: =IFERROR(VLOOKUP(K7,科目・教員!$A$2:$B$342,2,0),"") -> 池田 真弓 | M8: =IFERROR(VLOOKUP(M7,科目・教員!$A$2:$B$342,2,0),"") | O8: =IFERROR(VLOOKUP(O7,科目・教員!$A$2:$B$342,2,0),"") | Q8: =IFERROR(VLOOKUP(Q7,科目・教員!$A$2:$B$342,2,0),"") | S8: =IFERROR(VLOOKUP(S7,科目・教員!$A$2:$B$342,2,0),"") | U8: 特別研究
B9: 使用教室 | C9: =VLOOKUP($C2,'2026年度(1年後期)'!$B$5:$N$207,COLUMN('2026年度(1年後期)'!$E$5)+1,0)&"" -> 101 | E9: =VLOOKUP($C2,'2026年度(2年後期)'!$B$5:$N$207,COLUMN('2026年度(2年後期)'!$E$5)+1,0)&"" -> 201 | G9: =VLOOKUP($C2,'2026年度(3年後期)'!$B$5:$N$207,COLUMN('2026年度(3年後期)'!$E$5)+1,0)&"" | I9: =VLOOKUP($C2,'2026年度(4年後期)'!$B$5:$N$206,COLUMN('2026年度(4年後期)'!$E$5)+1,0)&"" -> 301 | K9: =VLOOKUP($C2,'2026年度(助産後期)'!$B$5:$N$207,COLUMN('2026年度(助産後期)'!$E$5)+1,0)&"" | M9: =VLOOKUP($C2,'2026年度(M1後期)'!$B$5:$N$207,COLUMN('2026年度(M1後期)'!$E$5)+1,0)&"" | O9: =VLOOKUP($C2,'2026年度(M2後期)'!$B$5:$N$207,COLUMN('2026年度(M2後期)'!$E$5)+1,0)&"" | Q9: =VLOOKUP($C2,'2026年度(D1後期)'!$B$5:$N$207,COLUMN('2026年度(D1後期)'!$E$5)+1,0)&"" | S9: =VLOOKUP($C2,'2026年度(D23後期)'!$B$5:$N$207,COLUMN('2026年度(D23後期)'!$E$5)+1,0)&"" | U9: M2尾澤
B10: 備 考 | U10: セミナールーム１
A11: 昼休み（12：30～13：30） | B11: 活動名 | Y11: １２：30～18：30 | Z11: =A11 -> 昼休み（12：30～13：30） | AF11: 演奏練習
B12: 責任者 | Y12: 卒業記念パーティ
B13: 使用教室 | Y13: 演奏会有志
B14: 備 考 | Y14: 講堂
A15: ３時限（13：30～15：00） | B15: 科目名 | C15: =VLOOKUP($C2,'2026年度(1年後期)'!$B$5:$N$207,COLUMN('2026年度(1年後期)'!$G$5),0)&"" -> 人体の構造と機能Ⅲ | E15: =VLOOKUP($C2,'2026年度(2年後期)'!$B$5:$N$207,COLUMN('2026年度(2年後期)'!$G$5),0)&"" -> 成人看護援助論Ⅱ | G15: =VLOOKUP($C2,'2026年度(3年後期)'!$B$5:$N$207,COLUMN('2026年度(3年後期)'!$G$5),0)&"" -> 領域別実習 | I15: =VLOOKUP($C2,'2026年度(4年後期)'!$B$5:$N$206,COLUMN('2026年度(4年後期)'!$G$5),0)&"" | K15: =VLOOKUP($C2,'2026年度(助産後期)'!$B$5:$N$207,COLUMN('2026年度(助産後期)'!$G$5),0)&"" -> 助産学実習Ⅰ | M15: =VLOOKUP($C2,'2026年度(M1後期)'!$B$5:$N$207,COLUMN('2026年度(M1後期)'!$G$5),0)&"" -> 感染症学特論 感染症学演習 成育看護学特論A-Ⅲ | O15: =VLOOKUP($C2,'2026年度(M2後期)'!$B$5:$N$207,COLUMN('2026年度(M2後期)'!$G$5),0)&"" -> 特別研究 | Q15: =VLOOKUP($C2,'2026年度(D1後期)'!$B$5:$N$207,COLUMN('2026年度(D1後期)'!$G$5),0)&"" | S15: =VLOOKUP($C2,'2026年度(D23後期)'!$B$5:$N$207,COLUMN('2026年度(D23後期)'!$G$5),0)&"" -> 特別研究 | U15: 3限 | V15: ３限 | W15: ３，４限 | Z15: =A15 -> ３時限（13：30～15：00） | AA15: 人体の構造と機能Ⅲ | AF15: 演奏練習 | AG15: 成人看護援助論Ⅱ | AW15: 卒研 小澤先生 | AZ15: 卒研 森下先生 | BI15: M1杉浦
B16: 教 官 | C16: =IFERROR(VLOOKUP(C15,科目・教員!$A$2:$B$342,2,0),"") -> 本間 典子 | E16: =IFERROR(VLOOKUP(E15,科目・教員!$A$2:$B$342,2,0),"") -> 藤澤 雄太 | G16: =IFERROR(VLOOKUP(G15,科目・教員!$A$2:$B$342,2,0),"") | I16: =IFERROR(VLOOKUP(I15,科目・教員!$A$2:$B$342,2,0),"") | K16: =IFERROR(VLOOKUP(K15,科目・教員!$A$2:$B$342,2,0),"") -> 池田 真弓 | M16: =IFERROR(VLOOKUP(M15,科目・教員!$A$2:$B$342,2,0),"") | O16: =IFERROR(VLOOKUP(O15,科目・教員!$A$2:$B$342,2,0),"") | Q16: =IFERROR(VLOOKUP(Q15,科目・教員!$A$2:$B$342,2,0),"") | S16: =IFERROR(VLOOKUP(S15,科目・教員!$A$2:$B$342,2,0),"") | U16: 卒研 | V16: 長寿 | W16: 卒業研究
B17: 使用教室 | C17: =VLOOKUP($C2,'2026年度(1年後期)'!$B$5:$N$207,COLUMN('2026年度(1年後期)'!$G$5)+1,0)&"" -> 101 | E17: =VLOOKUP($C2,'2026年度(2年後期)'!$B$5:$N$207,COLUMN('2026年度(2年後期)'!$G$5)+1,0)&"" -> 201 | G17: =VLOOKUP($C2,'2026年度(3年後期)'!$B$5:$N$207,COLUMN('2026年度(3年後期)'!$G$5)+1,0)&"" | I17: =VLOOKUP($C2,'2026年度(4年後期)'!$B$5:$N$206,COLUMN('2026年度(4年後期)'!$G$5)+1,0)&"" | K17: =VLOOKUP($C2,'2026年度(助産後期)'!$B$5:$N$207,COLUMN('2026年度(助産後期)'!$G$5)+1,0)&"" | M17: =VLOOKUP($C2,'2026年度(M1後期)'!$B$5:$N$207,COLUMN('2026年度(M1後期)'!$G$5)+1,0)&"" | O17: =VLOOKUP($C2,'2026年度(M2後期)'!$B$5:$N$207,COLUMN('2026年度(M2後期)'!$G$5)+1,0)&"" | Q17: =VLOOKUP($C2,'2026年度(D1後期)'!$B$5:$N$207,COLUMN('2026年度(D1後期)'!$G$5)+1,0)&"" | S17: =VLOOKUP($C2,'2026年度(D23後期)'!$B$5:$N$207,COLUMN('2026年度(D23後期)'!$G$5)+1,0)&"" | U17: 小澤先生 | V17: M1杉浦 | W17: 森下先生
B18: 備 考 | U18: 301教室 | V18: セミナールーム１ | W18: ３０４教室
A19: ４時限（15：10～16：40） | B19: 科目名 | C19: =VLOOKUP($C2,'2026年度(1年後期)'!$B$5:$N$207,COLUMN('2026年度(1年後期)'!$I$5),0)&"" | E19: =VLOOKUP($C2,'2026年度(2年後期)'!$B$5:$N$207,COLUMN('2026年度(2年後期)'!$I$5),0)&"" -> 母性看護援助論Ⅰ | G19: =VLOOKUP($C2,'2026年度(3年後期)'!$B$5:$N$207,COLUMN('2026年度(3年後期)'!$I$5),0)&"" -> 領域別実習 | I19: =VLOOKUP($C2,'2026年度(4年後期)'!$B$5:$N$206,COLUMN('2026年度(4年後期)'!$I$5),0)&"" | K19: =VLOOKUP($C2,'2026年度(助産後期)'!$B$5:$N$207,COLUMN('2026年度(助産後期)'!$I$5),0)&"" -> 助産学実習Ⅰ | M19: =VLOOKUP($C2,'2026年度(M1後期)'!$B$5:$N$207,COLUMN('2026年度(M1後期)'!$I$5),0)&"" -> 感染症学特論 感染症学演習 成育看護学特論A-Ⅲ | O19: =VLOOKUP($C2,'2026年度(M2後期)'!$B$5:$N$207,COLUMN('2026年度(M2後期)'!$I$5),0)&"" -> 特別研究 | Q19: =VLOOKUP($C2,'2026年度(D1後期)'!$B$5:$N$207,COLUMN('2026年度(D1後期)'!$I$5),0)&"" | S19: =VLOOKUP($C2,'2026年度(D23後期)'!$B$5:$N$207,COLUMN('2026年度(D23後期)'!$I$5),0)&"" -> 特別研究 | W19: １５：００～１７：００ | X19: 15:10～19：00 | Z19: =A19 -> ４時限（15：10～16：40） | AF19: 演奏練習 | AG19: 母性看護援助論Ⅰ | AZ19: 卒研 森下先生 | BK19: M2和田 | BN19: ウィンドアンサンブル
B20: 教 官 | C20: =IFERROR(VLOOKUP(C19,科目・教員!$A$2:$B$342,2,0),"") | E20: =IFERROR(VLOOKUP(E19,科目・教員!$A$2:$B$342,2,0),"") -> 日置 智華子 | G20: =IFERROR(VLOOKUP(G19,科目・教員!$A$2:$B$342,2,0),"") | I20: =IFERROR(VLOOKUP(I19,科目・教員!$A$2:$B$342,2,0),"") | K20: =IFERROR(VLOOKUP(K19,科目・教員!$A$2:$B$342,2,0),"") -> 池田 真弓 | M20: =IFERROR(VLOOKUP(M19,科目・教員!$A$2:$B$342,2,0),"") | O20: =IFERROR(VLOOKUP(O19,科目・教員!$A$2:$B$342,2,0),"") | Q20: =IFERROR(VLOOKUP(Q19,科目・教員!$A$2:$B$342,2,0),"") | S20: =IFERROR(VLOOKUP(S19,科目・教員!$A$2:$B$342,2,0),"") | W20: 特別研究 | X20: 清秋祭演奏練習
B21: 使用教室 | C21: =VLOOKUP($C2,'2026年度(1年後期)'!$B$5:$N$207,COLUMN('2026年度(1年後期)'!$I$5)+1,0)&"" | E21: =VLOOKUP($C2,'2026年度(2年後期)'!$B$5:$N$207,COLUMN('2026年度(2年後期)'!$I$5)+1,0)&"" -> 201 | G21: =VLOOKUP($C2,'2026年度(3年後期)'!$B$5:$N$207,COLUMN('2026年度(3年後期)'!$I$5)+1,0)&"" | I21: =VLOOKUP($C2,'2026年度(4年後期)'!$B$5:$N$206,COLUMN('2026年度(4年後期)'!$I$5)+1,0)&"" | K21: =VLOOKUP($C2,'2026年度(助産後期)'!$B$5:$N$207,COLUMN('2026年度(助産後期)'!$I$5)+1,0)&"" | M21: =VLOOKUP($C2,'2026年度(M1後期)'!$B$5:$N$207,COLUMN('2026年度(M1後期)'!$I$5)+1,0)&"" | O21: =VLOOKUP($C2,'2026年度(M2後期)'!$B$5:$N$207,COLUMN('2026年度(M2後期)'!$I$5)+1,0)&"" | Q21: =VLOOKUP($C2,'2026年度(D1後期)'!$B$5:$N$207,COLUMN('2026年度(D1後期)'!$I$5)+1,0)&"" | S21: =VLOOKUP($C2,'2026年度(D23後期)'!$B$5:$N$207,COLUMN('2026年度(D23後期)'!$I$5)+1,0)&"" | W21: M2和田 | X21: ウィンドアンサンブル
B22: 備 考 | W22: セミナールーム３ | X22: 大講義室
A23: ５時限（16：50～18：20） | B23: 科目名 | C23: =VLOOKUP($C2,'2026年度(1年後期)'!$B$5:$N$207,COLUMN('2026年度(1年後期)'!$K$5),0)&"" | E23: =VLOOKUP($C2,'2026年度(2年後期)'!$B$5:$N$207,COLUMN('2026年度(2年後期)'!$K$5),0)&"" | G23: =VLOOKUP($C2,'2026年度(3年後期)'!$B$5:$N$207,COLUMN('2026年度(3年後期)'!$K$5),0)&"" | I23: =VLOOKUP($C2,'2026年度(4年後期)'!$B$5:$N$206,COLUMN('2026年度(4年後期)'!$K$5),0)&"" | K23: =VLOOKUP($C2,'2026年度(助産後期)'!$B$5:$N$207,COLUMN('2026年度(助産後期)'!$K$5),0)&"" | M23: =VLOOKUP($C2,'2026年度(M1後期)'!$B$5:$N$207,COLUMN('2026年度(M1後期)'!$K$5),0)&"" | O23: =VLOOKUP($C2,'2026年度(M2後期)'!$B$5:$N$207,COLUMN('2026年度(M2後期)'!$K$5),0)&"" | Q23: =VLOOKUP($C2,'2026年度(D1後期)'!$B$5:$N$207,COLUMN('2026年度(D1後期)'!$K$5),0)&"" | S23: =VLOOKUP($C2,'2026年度(D23後期)'!$B$5:$N$207,COLUMN('2026年度(D23後期)'!$K$5),0)&"" | U23: 5限 | V23: 16：50～ | W23: １６：４０～18：20 | Z23: =A23 -> ５時限（16：50～18：20） | AA23: 手話サークル | AF23: 演奏練習 | AX23: 清秋祭執行委員会会議 | BJ23: M1松本 | BK23: M2和田 | BN23: ウィンドアンサンブル
B24: 教 官 | C24: =IFERROR(VLOOKUP(C23,科目・教員!$A$2:$B$342,2,0),"") | E24: =IFERROR(VLOOKUP(E23,科目・教員!$A$2:$B$342,2,0),"") | G24: =IFERROR(VLOOKUP(G23,科目・教員!$A$2:$B$342,2,0),"") | I24: =IFERROR(VLOOKUP(I23,科目・教員!$A$2:$B$342,2,0),"") | K24: =IFERROR(VLOOKUP(K23,科目・教員!$A$2:$B$342,2,0),"") | M24: =IFERROR(VLOOKUP(M23,科目・教員!$A$2:$B$342,2,0),"") | O24: =IFERROR(VLOOKUP(O23,科目・教員!$A$2:$B$342,2,0),"") | Q24: =IFERROR(VLOOKUP(Q23,科目・教員!$A$2:$B$342,2,0),"") | S24: =IFERROR(VLOOKUP(S23,科目・教員!$A$2:$B$342,2,0),"") | U24: 成人看護学 | V24: 清秋祭執行会議 | W24: 手話サークル
B25: 使用教室 | C25: =VLOOKUP($C2,'2026年度(1年後期)'!$B$5:$N$207,COLUMN('2026年度(1年後期)'!$K$5)+1,0)&"" | E25: =VLOOKUP($C2,'2026年度(2年後期)'!$B$5:$N$207,COLUMN('2026年度(2年後期)'!$K$5)+1,0)&"" | G25: =VLOOKUP($C2,'2026年度(3年後期)'!$B$5:$N$207,COLUMN('2026年度(3年後期)'!$K$5)+1,0)&"" | I25: =VLOOKUP($C2,'2026年度(4年後期)'!$B$5:$N$206,COLUMN('2026年度(4年後期)'!$K$5)+1,0)&"" | K25: =VLOOKUP($C2,'2026年度(助産後期)'!$B$5:$N$207,COLUMN('2026年度(助産後期)'!$K$5)+1,0)&"" | M25: =VLOOKUP($C2,'2026年度(M1後期)'!$B$5:$N$207,COLUMN('2026年度(M1後期)'!$K$5)+1,0)&"" | O25: =VLOOKUP($C2,'2026年度(M2後期)'!$B$5:$N$207,COLUMN('2026年度(M2後期)'!$K$5)+1,0)&"" | Q25: =VLOOKUP($C2,'2026年度(D1後期)'!$B$5:$N$207,COLUMN('2026年度(D1後期)'!$K$5)+1,0)&"" | S25: =VLOOKUP($C2,'2026年度(D23後期)'!$B$5:$N$207,COLUMN('2026年度(D23後期)'!$K$5)+1,0)&"" | U25: M1松本 | V25: 執行委員会 | W25: １０１教室
B26: 備 考 | U26: セミナールーム2 | V26: ３０２教室
C27: =C2+1 -> 46297 | U27: =C27 -> 46297 | AA27: 101 | AB27: 102 | AC27: 103 | AD27: 在宅実習室 | AE27: 成人実習室 | AF27: 講堂 | AG27: 201 | AH27: 202 | AI27: 203 | AJ27: 204 | AK27: 205 | AL27: 基礎実習室 | AM27: 母性・小児実習室 | AN27: 演習21 | AO27: 演習22 | AP27: 演習23 | AQ27: 演習24 | AR27: 演習25 | AS27: 演習26 | AT27: 演習27 | AU27: 演習28 | AV27: 演習29 | AW27: 301 | AX27: 302 | AY27: 303 | AZ27: 304 | BA27: 臨床１ | BB27: 臨床２ | BC27: LL1 | BD27: LL2 | BE27: 実験室 | BF27: 情報処理室 | BG27: 演習31 | BH27: 演習32 | BI27: セミナー室１ | BJ27: セミナー室２ | BK27: セミナー室3 | BL27: セミナー室4 | BM27: セミナー室5 | BN27: 大講義室 | BO27: アリーナ | BP27: 研修１ | BQ27: 研修３ | BR27: 研修４ | BS27: 研修５ | BT27: 研修６ | BU27: 研修７ | BV27: 視聴覚室
A28: １時限（09：20～10：50） | B28: 科目名 | C28: =VLOOKUP($C27,'2026年度(1年後期)'!$B$5:$N$207,COLUMN('2026年度(1年後期)'!$C$5),0)&"" | E28: =VLOOKUP($C27,'2026年度(2年後期)'!$B$5:$N$207,COLUMN('2026年度(2年後期)'!$C$5),0)&"" -> 看護基礎理論 | G28: =VLOOKUP($C27,'2026年度(3年後期)'!$B$5:$N$207,COLUMN('2026年度(3年後期)'!$C$5),0)&"" -> 領域別実習 | I28: =VLOOKUP($C27,'2026年度(4年後期)'!$B$5:$N$206,COLUMN('2026年度(4年後期)'!$C$5),0)&"" -> 卒業研究Ⅱ | K28: =VLOOKUP($C27,'2026年度(助産後期)'!$B$5:$N$207,COLUMN('2026年度(助産後期)'!$C$5),0)&"" -> 助産学実習Ⅰ | M28: =VLOOKUP($C27,'2026年度(M1後期)'!$B$5:$N$207,COLUMN('2026年度(M1後期)'!$C$5),0)&"" -> 看護継続教育 長寿看護学演習A-Ⅰ | O28: =VLOOKUP($C27,'2026年度(M2後期)'!$B$5:$N$207,COLUMN('2026年度(M2後期)'!$C$5),0)&"" -> 感染管理看護学演習A-Ⅱ 特別研究 | Q28: =VLOOKUP($C27,'2026年度(D1後期)'!$B$5:$N$207,COLUMN('2026年度(D1後期)'!$C$5),0)&"" -> 精神看護学演習Ｂ | S28: =VLOOKUP($C27,'2026年度(D23後期)'!$B$5:$N$207,COLUMN('2026年度(D23後期)'!$C$5),0)&"" -> 特別研究 | Z28: =A28 -> １時限（09：20～10：50） | AG28: 看護基礎理論 | BA28: 看護継続教育
B29: 教 官 | C29: =IFERROR(VLOOKUP(C28,科目・教員!$A$2:$B$342,2,0),"") | E29: =IFERROR(VLOOKUP(E28,科目・教員!$A$2:$B$342,2,0),"") -> 水野 正之 | G29: =IFERROR(VLOOKUP(G28,科目・教員!$A$2:$B$342,2,0),"") | I29: =IFERROR(VLOOKUP(I28,科目・教員!$A$2:$B$342,2,0),"") -> 各担当教員 | K29: =IFERROR(VLOOKUP(K28,科目・教員!$A$2:$B$342,2,0),"") -> 池田 真弓 | M29: =IFERROR(VLOOKUP(M28,科目・教員!$A$2:$B$342,2,0),"") | O29: =IFERROR(VLOOKUP(O28,科目・教員!$A$2:$B$342,2,0),"") | Q29: =IFERROR(VLOOKUP(Q28,科目・教員!$A$2:$B$342,2,0),"") | S29: =IFERROR(VLOOKUP(S28,科目・教員!$A$2:$B$342,2,0),"")
B30: 使用教室 | C30: =VLOOKUP($C27,'2026年度(1年後期)'!$B$5:$N$207,COLUMN('2026年度(1年後期)'!$C$5)+1,0)&"" | E30: =VLOOKUP($C27,'2026年度(2年後期)'!$B$5:$N$207,COLUMN('2026年度(2年後期)'!$C$5)+1,0)&"" -> 201 | G30: =VLOOKUP($C27,'2026年度(3年後期)'!$B$5:$N$207,COLUMN('2026年度(3年後期)'!$C$5)+1,0)&"" | I30: =VLOOKUP($C27,'2026年度(4年後期)'!$B$5:$N$206,COLUMN('2026年度(4年後期)'!$C$5)+1,0)&"" | K30: =VLOOKUP($C27,'2026年度(助産後期)'!$B$5:$N$207,COLUMN('2026年度(助産後期)'!$C$5)+1,0)&"" | M30: =VLOOKUP($C27,'2026年度(M1後期)'!$B$5:$N$207,COLUMN('2026年度(M1後期)'!$C$5)+1,0)&"" -> 教育:臨床講義室1 | O30: =VLOOKUP($C27,'2026年度(M2後期)'!$B$5:$N$207,COLUMN('2026年度(M2後期)'!$C$5)+1,0)&"" | Q30: =VLOOKUP($C27,'2026年度(D1後期)'!$B$5:$N$207,COLUMN('2026年度(D1後期)'!$C$5)+1,0)&"" | S30: =VLOOKUP($C27,'2026年度(D23後期)'!$B$5:$N$207,COLUMN('2026年度(D23後期)'!$C$5)+1,0)&""
B31: 備 考
A32: ２時限（11：00～12：30） | B32: 科目名 | C32: =VLOOKUP($C27,'2026年度(1年後期)'!$B$5:$N$207,COLUMN('2026年度(1年後期)'!$E$5),0)&"" -> 食と健康 | E32: =VLOOKUP($C27,'2026年度(2年後期)'!$B$5:$N$207,COLUMN('2026年度(2年後期)'!$E$5),0)&"" -> 小児看護学概論 | G32: =VLOOKUP($C27,'2026年度(3年後期)'!$B$5:$N$207,COLUMN('2026年度(3年後期)'!$E$5),0)&"" -> 領域別実習 | I32: =VLOOKUP($C27,'2026年度(4年後期)'!$B$5:$N$206,COLUMN('2026年度(4年後期)'!$E$5),0)&"" -> 卒業研究Ⅱ | K32: =VLOOKUP($C27,'2026年度(助産後期)'!$B$5:$N$207,COLUMN('2026年度(助産後期)'!$E$5),0)&"" -> 助産学実習Ⅰ | M32: =VLOOKUP($C27,'2026年度(M1後期)'!$B$5:$N$207,COLUMN('2026年度(M1後期)'!$E$5),0)&"" -> 看護継続教育 長寿看護学演習A-Ⅰ | O32: =VLOOKUP($C27,'2026年度(M2後期)'!$B$5:$N$207,COLUMN('2026年度(M2後期)'!$E$5),0)&"" -> 感染管理看護学演習A-Ⅱ 特別研究 | Q32: =VLOOKUP($C27,'2026年度(D1後期)'!$B$5:$N$207,COLUMN('2026年度(D1後期)'!$E$5),0)&"" -> 精神看護学演習Ｂ | S32: =VLOOKUP($C27,'2026年度(D23後期)'!$B$5:$N$207,COLUMN('2026年度(D23後期)'!$E$5),0)&"" -> 特別研究 | Z32: =A32 -> ２時限（11：00～12：30） | AA32: 食と健康 | AG32: 小児看護学概論 | BA32: 看護継続教育
B33: 教 官 | C33: =IFERROR(VLOOKUP(C32,科目・教員!$A$2:$B$342,2,0),"") -> 本間 典子 | E33: =IFERROR(VLOOKUP(E32,科目・教員!$A$2:$B$342,2,0),"") -> 来生 奈巳子 | G33: =IFERROR(VLOOKUP(G32,科目・教員!$A$2:$B$342,2,0),"") | I33: =IFERROR(VLOOKUP(I32,科目・教員!$A$2:$B$342,2,0),"") -> 各担当教員 | K33: =IFERROR(VLOOKUP(K32,科目・教員!$A$2:$B$342,2,0),"") -> 池田 真弓 | M33: =IFERROR(VLOOKUP(M32,科目・教員!$A$2:$B$342,2,0),"") | O33: =IFERROR(VLOOKUP(O32,科目・教員!$A$2:$B$342,2,0),"") | Q33: =IFERROR(VLOOKUP(Q32,科目・教員!$A$2:$B$342,2,0),"") | S33: =IFERROR(VLOOKUP(S32,科目・教員!$A$2:$B$342,2,0),"")
B34: 使用教室 | C34: =VLOOKUP($C27,'2026年度(1年後期)'!$B$5:$N$207,COLUMN('2026年度(1年後期)'!$E$5)+1,0)&"" -> 101 | E34: =VLOOKUP($C27,'2026年度(2年後期)'!$B$5:$N$207,COLUMN('2026年度(2年後期)'!$E$5)+1,0)&"" -> 201 | G34: =VLOOKUP($C27,'2026年度(3年後期)'!$B$5:$N$207,COLUMN('2026年度(3年後期)'!$E$5)+1,0)&"" | I34: =VLOOKUP($C27,'2026年度(4年後期)'!$B$5:$N$206,COLUMN('2026年度(4年後期)'!$E$5)+1,0)&"" | K34: =VLOOKUP($C27,'2026年度(助産後期)'!$B$5:$N$207,COLUMN('2026年度(助産後期)'!$E$5)+1,0)&"" | M34: =VLOOKUP($C27,'2026年度(M1後期)'!$B$5:$N$207,COLUMN('2026年度(M1後期)'!$E$5)+1,0)&"" -> 教育:臨床講義室1 | O34: =VLOOKUP($C27,'2026年度(M2後期)'!$B$5:$N$207,COLUMN('2026年度(M2後期)'!$E$5)+1,0)&"" | Q34: =VLOOKUP($C27,'2026年度(D1後期)'!$B$5:$N$207,COLUMN('2026年度(D1後期)'!$E$5)+1,0)&"" | S34: =VLOOKUP($C27,'2026年度(D23後期)'!$B$5:$N$207,COLUMN('2026年度(D23後期)'!$E$5)+1,0)&""
B35: 備 考
A36: 昼休み（12：30～13：30） | B36: 活動名 | Z36: =A36 -> 昼休み（12：30～13：30）
B37: 責任者
B38: 使用教室
B39: 備 考
A40: ３時限（13：30～15：00） | B40: 科目名 | C40: =VLOOKUP($C27,'2026年度(1年後期)'!$B$5:$N$207,COLUMN('2026年度(1年後期)'!$G$5),0)&"" -> 疫学・保健統計学Ⅱ | E40: =VLOOKUP($C27,'2026年度(2年後期)'!$B$5:$N$207,COLUMN('2026年度(2年後期)'!$G$5),0)&"" -> 基礎看護学実習Ⅱ オリエンテーション① | G40: =VLOOKUP($C27,'2026年度(3年後期)'!$B$5:$N$207,COLUMN('2026年度(3年後期)'!$G$5),0)&"" -> 領域別実習 | I40: =VLOOKUP($C27,'2026年度(4年後期)'!$B$5:$N$206,COLUMN('2026年度(4年後期)'!$G$5),0)&"" | K40: =VLOOKUP($C27,'2026年度(助産後期)'!$B$5:$N$207,COLUMN('2026年度(助産後期)'!$G$5),0)&"" -> 助産学実習Ⅰ | M40: =VLOOKUP($C27,'2026年度(M1後期)'!$B$5:$N$207,COLUMN('2026年度(M1後期)'!$G$5),0)&"" -> 看護統計学 | O40: =VLOOKUP($C27,'2026年度(M2後期)'!$B$5:$N$207,COLUMN('2026年度(M2後期)'!$G$5),0)&"" -> 特別研究 | Q40: =VLOOKUP($C27,'2026年度(D1後期)'!$B$5:$N$207,COLUMN('2026年度(D1後期)'!$G$5),0)&"" | S40: =VLOOKUP($C27,'2026年度(D23後期)'!$B$5:$N$207,COLUMN('2026年度(D23後期)'!$G$5),0)&"" -> 特別研究 | U40: 3限 | Z40: =A40 -> ３時限（13：30～15：00） | AA40: 疫学･保健統計学Ⅱ | AG40: 基礎看護学実習Ⅱオリエンテーション | AH40: 基礎看護学実習Ⅱオリエンテーション | BD40: 研究業務係 日當 | BF40: 看護統計学
...

Sheet 2026年11月
A1: 46327 | C1: １年 | E1: ２年 | G1: ３年 | I1: ４年 | K1: 助産 | M1: 研究課程部 Ｍ１ | O1: 研究課程部 Ｍ２ | Q1: 研究課程部 Ｄ１ | S1: 研究課程部 Ｄ２３ | U1: =A1 -> 46327 | V1: 授業外その他教室等管理スケジュール | AA1: １階 | AG1: ２階 | AW1: ３階 | BI1: ４階 | BN1: 体育棟 | BP1: 研修棟
C2: =A1 -> 46327 | U2: =C2 -> 46327 | AA2: 101 | AB2: 102 | AC2: 103 | AD2: 在宅実習室 | AE2: 成人実習室 | AF2: 講堂 | AG2: 201 | AH2: 202 | AI2: 203 | AJ2: 204 | AK2: 205 | AL2: 基礎実習室 | AM2: 母性・小児実習室 | AN2: 演習21 | AO2: 演習22 | AP2: 演習23 | AQ2: 演習24 | AR2: 演習25 | AS2: 演習26 | AT2: 演習27 | AU2: 演習28 | AV2: 演習29 | AW2: 301 | AX2: 302 | AY2: 303 | AZ2: 304 | BA2: 臨床１ | BB2: 臨床２ | BC2: LL1 | BD2: LL2 | BE2: 実験室 | BF2: 情報処理室 | BG2: 演習31 | BH2: 演習32 | BI2: セミナー室１ | BJ2: セミナー室２ | BK2: セミナー室3 | BL2: セミナー室4 | BM2: セミナー室5 | BN2: 大講義室 | BO2: アリーナ | BP2: 研修１ | BQ2: 研修３ | BR2: 研修４ | BS2: 研修５ | BT2: 研修６ | BU2: 研修７ | BV2: 視聴覚室
A3: １時限（09：20～10：50） | B3: 科目名 | C3: =VLOOKUP($C2,'2026年度(1年後期)'!$B$5:$N$207,COLUMN('2026年度(1年後期)'!$C$5),0)&"" | E3: =VLOOKUP($C2,'2026年度(2年後期)'!$B$5:$N$207,COLUMN('2026年度(2年後期)'!$C$5),0)&"" | G3: =VLOOKUP($C2,'2026年度(3年後期)'!$B$5:$N$207,COLUMN('2026年度(3年後期)'!$C$5),0)&"" | I3: =VLOOKUP($C2,'2026年度(4年後期)'!$B$5:$N$206,COLUMN('2026年度(4年後期)'!$C$5),0)&"" | K3: =VLOOKUP($C2,'2026年度(助産後期)'!$B$5:$N$207,COLUMN('2026年度(助産後期)'!$C$5),0)&"" | M3: =VLOOKUP($C2,'2026年度(M1後期)'!$B$5:$N$207,COLUMN('2026年度(M1後期)'!$C$5),0)&"" | O3: =VLOOKUP($C2,'2026年度(M2後期)'!$B$5:$N$207,COLUMN('2026年度(M2後期)'!$C$5),0)&"" | Q3: =VLOOKUP($C2,'2026年度(D1後期)'!$B$5:$N$207,COLUMN('2026年度(D1後期)'!$C$5),0)&"" | S3: =VLOOKUP($C2,'2026年度(D23後期)'!$B$5:$N$207,COLUMN('2026年度(D23後期)'!$C$5),0)&"" | Z3: =A3 -> １時限（09：20～10：50）
B4: 教 官 | C4: =IFERROR(VLOOKUP(C3,科目・教員!$A$2:$B$342,2,0),"") | E4: =IFERROR(VLOOKUP(E3,科目・教員!$A$2:$B$342,2,0),"") | G4: =IFERROR(VLOOKUP(G3,科目・教員!$A$2:$B$342,2,0),"") | I4: =IFERROR(VLOOKUP(I3,科目・教員!$A$2:$B$342,2,0),"") | K4: =IFERROR(VLOOKUP(K3,科目・教員!$A$2:$B$342,2,0),"") | M4: =IFERROR(VLOOKUP(M3,科目・教員!$A$2:$B$342,2,0),"") | O4: =IFERROR(VLOOKUP(O3,科目・教員!$A$2:$B$342,2,0),"") | Q4: =IFERROR(VLOOKUP(Q3,科目・教員!$A$2:$B$342,2,0),"") | S4: =IFERROR(VLOOKUP(S3,科目・教員!$A$2:$B$342,2,0),"")
B5: 使用教室 | C5: =VLOOKUP($C2,'2026年度(1年後期)'!$B$5:$N$207,COLUMN('2026年度(1年後期)'!$C$5)+1,0)&"" | E5: =VLOOKUP($C2,'2026年度(2年後期)'!$B$5:$N$207,COLUMN('2026年度(2年後期)'!$C$5)+1,0)&"" | G5: =VLOOKUP($C2,'2026年度(3年後期)'!$B$5:$N$207,COLUMN('2026年度(3年後期)'!$C$5)+1,0)&"" | I5: =VLOOKUP($C2,'2026年度(4年後期)'!$B$5:$N$206,COLUMN('2026年度(4年後期)'!$C$5)+1,0)&"" | K5: =VLOOKUP($C2,'2026年度(助産後期)'!$B$5:$N$207,COLUMN('2026年度(助産後期)'!$C$5)+1,0)&"" | M5: =VLOOKUP($C2,'2026年度(M1後期)'!$B$5:$N$207,COLUMN('2026年度(M1後期)'!$C$5)+1,0)&"" | O5: =VLOOKUP($C2,'2026年度(M2後期)'!$B$5:$N$207,COLUMN('2026年度(M2後期)'!$C$5)+1,0)&"" | Q5: =VLOOKUP($C2,'2026年度(D1後期)'!$B$5:$N$207,COLUMN('2026年度(D1後期)'!$C$5)+1,0)&"" | S5: =VLOOKUP($C2,'2026年度(D23後期)'!$B$5:$N$207,COLUMN('2026年度(D23後期)'!$C$5)+1,0)&""
B6: 備 考
A7: ２時限（11：00～12：30） | B7: 科目名 | C7: =VLOOKUP($C2,'2026年度(1年後期)'!$B$5:$N$207,COLUMN('2026年度(1年後期)'!$E$5),0)&"" | E7: =VLOOKUP($C2,'2026年度(2年後期)'!$B$5:$N$207,COLUMN('2026年度(2年後期)'!$E$5),0)&"" | G7: =VLOOKUP($C2,'2026年度(3年後期)'!$B$5:$N$207,COLUMN('2026年度(3年後期)'!$E$5),0)&"" | I7: =VLOOKUP($C2,'2026年度(4年後期)'!$B$5:$N$206,COLUMN('2026年度(4年後期)'!$E$5),0)&"" | K7: =VLOOKUP($C2,'2026年度(助産後期)'!$B$5:$N$207,COLUMN('2026年度(助産後期)'!$E$5),0)&"" | M7: =VLOOKUP($C2,'2026年度(M1後期)'!$B$5:$N$207,COLUMN('2026年度(M1後期)'!$E$5),0)&"" | O7: =VLOOKUP($C2,'2026年度(M2後期)'!$B$5:$N$207,COLUMN('2026年度(M2後期)'!$E$5),0)&"" | Q7: =VLOOKUP($C2,'2026年度(D1後期)'!$B$5:$N$207,COLUMN('2026年度(D1後期)'!$E$5),0)&"" | S7: =VLOOKUP($C2,'2026年度(D23後期)'!$B$5:$N$207,COLUMN('2026年度(D23後期)'!$E$5),0)&"" | Z7: =A7 -> ２時限（11：00～12：30）
B8: 教 官 | C8: =IFERROR(VLOOKUP(C7,科目・教員!$A$2:$B$342,2,0),"") | E8: =IFERROR(VLOOKUP(E7,科目・教員!$A$2:$B$342,2,0),"") | G8: =IFERROR(VLOOKUP(G7,科目・教員!$A$2:$B$342,2,0),"") | I8: =IFERROR(VLOOKUP(I7,科目・教員!$A$2:$B$342,2,0),"") | K8: =IFERROR(VLOOKUP(K7,科目・教員!$A$2:$B$342,2,0),"") | M8: =IFERROR(VLOOKUP(M7,科目・教員!$A$2:$B$342,2,0),"") | O8: =IFERROR(VLOOKUP(O7,科目・教員!$A$2:$B$342,2,0),"") | Q8: =IFERROR(VLOOKUP(Q7,科目・教員!$A$2:$B$342,2,0),"") | S8: =IFERROR(VLOOKUP(S7,科目・教員!$A$2:$B$342,2,0),"")
B9: 使用教室 | C9: =VLOOKUP($C2,'2026年度(1年後期)'!$B$5:$N$207,COLUMN('2026年度(1年後期)'!$E$5)+1,0)&"" | E9: =VLOOKUP($C2,'2026年度(2年後期)'!$B$5:$N$207,COLUMN('2026年度(2年後期)'!$E$5)+1,0)&"" | G9: =VLOOKUP($C2,'2026年度(3年後期)'!$B$5:$N$207,COLUMN('2026年度(3年後期)'!$E$5)+1,0)&"" | I9: =VLOOKUP($C2,'2026年度(4年後期)'!$B$5:$N$206,COLUMN('2026年度(4年後期)'!$E$5)+1,0)&"" | K9: =VLOOKUP($C2,'2026年度(助産後期)'!$B$5:$N$207,COLUMN('2026年度(助産後期)'!$E$5)+1,0)&"" | M9: =VLOOKUP($C2,'2026年度(M1後期)'!$B$5:$N$207,COLUMN('2026年度(M1後期)'!$E$5)+1,0)&"" | O9: =VLOOKUP($C2,'2026年度(M2後期)'!$B$5:$N$207,COLUMN('2026年度(M2後期)'!$E$5)+1,0)&"" | Q9: =VLOOKUP($C2,'2026年度(D1後期)'!$B$5:$N$207,COLUMN('2026年度(D1後期)'!$E$5)+1,0)&"" | S9: =VLOOKUP($C2,'2026年度(D23後期)'!$B$5:$N$207,COLUMN('2026年度(D23後期)'!$E$5)+1,0)&""
B10: 備 考
A11: 昼休み（12：30～13：30） | B11: 活動名 | Z11: =A11 -> 昼休み（12：30～13：30）
B12: 責任者
B13: 使用教室
B14: 備 考
A15: ３時限（13：30～15：00） | B15: 科目名 | C15: =VLOOKUP($C2,'2026年度(1年後期)'!$B$5:$N$207,COLUMN('2026年度(1年後期)'!$G$5),0)&"" | E15: =VLOOKUP($C2,'2026年度(2年後期)'!$B$5:$N$207,COLUMN('2026年度(2年後期)'!$G$5),0)&"" | G15: =VLOOKUP($C2,'2026年度(3年後期)'!$B$5:$N$207,COLUMN('2026年度(3年後期)'!$G$5),0)&"" | I15: =VLOOKUP($C2,'2026年度(4年後期)'!$B$5:$N$206,COLUMN('2026年度(4年後期)'!$G$5),0)&"" | K15: =VLOOKUP($C2,'2026年度(助産後期)'!$B$5:$N$207,COLUMN('2026年度(助産後期)'!$G$5),0)&"" | M15: =VLOOKUP($C2,'2026年度(M1後期)'!$B$5:$N$207,COLUMN('2026年度(M1後期)'!$G$5),0)&"" | O15: =VLOOKUP($C2,'2026年度(M2後期)'!$B$5:$N$207,COLUMN('2026年度(M2後期)'!$G$5),0)&"" | Q15: =VLOOKUP($C2,'2026年度(D1後期)'!$B$5:$N$207,COLUMN('2026年度(D1後期)'!$G$5),0)&"" | S15: =VLOOKUP($C2,'2026年度(D23後期)'!$B$5:$N$207,COLUMN('2026年度(D23後期)'!$G$5),0)&"" | Z15: =A15 -> ３時限（13：30～15：00）
B16: 教 官 | C16: =IFERROR(VLOOKUP(C15,科目・教員!$A$2:$B$342,2,0),"") | E16: =IFERROR(VLOOKUP(E15,科目・教員!$A$2:$B$342,2,0),"") | G16: =IFERROR(VLOOKUP(G15,科目・教員!$A$2:$B$342,2,0),"") | I16: =IFERROR(VLOOKUP(I15,科目・教員!$A$2:$B$342,2,0),"") | K16: =IFERROR(VLOOKUP(K15,科目・教員!$A$2:$B$342,2,0),"") | M16: =IFERROR(VLOOKUP(M15,科目・教員!$A$2:$B$342,2,0),"") | O16: =IFERROR(VLOOKUP(O15,科目・教員!$A$2:$B$342,2,0),"") | Q16: =IFERROR(VLOOKUP(Q15,科目・教員!$A$2:$B$342,2,0),"") | S16: =IFERROR(VLOOKUP(S15,科目・教員!$A$2:$B$342,2,0),"")
B17: 使用教室 | C17: =VLOOKUP($C2,'2026年度(1年後期)'!$B$5:$N$207,COLUMN('2026年度(1年後期)'!$G$5)+1,0)&"" | E17: =VLOOKUP($C2,'2026年度(2年後期)'!$B$5:$N$207,COLUMN('2026年度(2年後期)'!$G$5)+1,0)&"" | G17: =VLOOKUP($C2,'2026年度(3年後期)'!$B$5:$N$207,COLUMN('2026年度(3年後期)'!$G$5)+1,0)&"" | I17: =VLOOKUP($C2,'2026年度(4年後期)'!$B$5:$N$206,COLUMN('2026年度(4年後期)'!$G$5)+1,0)&"" | K17: =VLOOKUP($C2,'2026年度(助産後期)'!$B$5:$N$207,COLUMN('2026年度(助産後期)'!$G$5)+1,0)&"" | M17: =VLOOKUP($C2,'2026年度(M1後期)'!$B$5:$N$207,COLUMN('2026年度(M1後期)'!$G$5)+1,0)&"" | O17: =VLOOKUP($C2,'2026年度(M2後期)'!$B$5:$N$207,COLUMN('2026年度(M2後期)'!$G$5)+1,0)&"" | Q17: =VLOOKUP($C2,'2026年度(D1後期)'!$B$5:$N$207,COLUMN('2026年度(D1後期)'!$G$5)+1,0)&"" | S17: =VLOOKUP($C2,'2026年度(D23後期)'!$B$5:$N$207,COLUMN('2026年度(D23後期)'!$G$5)+1,0)&""
B18: 備 考
A19: ４時限（15：10～16：40） | B19: 科目名 | C19: =VLOOKUP($C2,'2026年度(1年後期)'!$B$5:$N$207,COLUMN('2026年度(1年後期)'!$I$5),0)&"" | E19: =VLOOKUP($C2,'2026年度(2年後期)'!$B$5:$N$207,COLUMN('2026年度(2年後期)'!$I$5),0)&"" | G19: =VLOOKUP($C2,'2026年度(3年後期)'!$B$5:$N$207,COLUMN('2026年度(3年後期)'!$I$5),0)&"" | I19: =VLOOKUP($C2,'2026年度(4年後期)'!$B$5:$N$206,COLUMN('2026年度(4年後期)'!$I$5),0)&"" | K19: =VLOOKUP($C2,'2026年度(助産後期)'!$B$5:$N$207,COLUMN('2026年度(助産後期)'!$I$5),0)&"" | M19: =VLOOKUP($C2,'2026年度(M1後期)'!$B$5:$N$207,COLUMN('2026年度(M1後期)'!$I$5),0)&"" | O19: =VLOOKUP($C2,'2026年度(M2後期)'!$B$5:$N$207,COLUMN('2026年度(M2後期)'!$I$5),0)&"" | Q19: =VLOOKUP($C2,'2026年度(D1後期)'!$B$5:$N$207,COLUMN('2026年度(D1後期)'!$I$5),0)&"" | S19: =VLOOKUP($C2,'2026年度(D23後期)'!$B$5:$N$207,COLUMN('2026年度(D23後期)'!$I$5),0)&"" | Z19: =A19 -> ４時限（15：10～16：40）
B20: 教 官 | C20: =IFERROR(VLOOKUP(C19,科目・教員!$A$2:$B$342,2,0),"") | E20: =IFERROR(VLOOKUP(E19,科目・教員!$A$2:$B$342,2,0),"") | G20: =IFERROR(VLOOKUP(G19,科目・教員!$A$2:$B$342,2,0),"") | I20: =IFERROR(VLOOKUP(I19,科目・教員!$A$2:$B$342,2,0),"") | K20: =IFERROR(VLOOKUP(K19,科目・教員!$A$2:$B$342,2,0),"") | M20: =IFERROR(VLOOKUP(M19,科目・教員!$A$2:$B$342,2,0),"") | O20: =IFERROR(VLOOKUP(O19,科目・教員!$A$2:$B$342,2,0),"") | Q20: =IFERROR(VLOOKUP(Q19,科目・教員!$A$2:$B$342,2,0),"") | S20: =IFERROR(VLOOKUP(S19,科目・教員!$A$2:$B$342,2,0),"")
B21: 使用教室 | C21: =VLOOKUP($C2,'2026年度(1年後期)'!$B$5:$N$207,COLUMN('2026年度(1年後期)'!$I$5)+1,0)&"" | E21: =VLOOKUP($C2,'2026年度(2年後期)'!$B$5:$N$207,COLUMN('2026年度(2年後期)'!$I$5)+1,0)&"" | G21: =VLOOKUP($C2,'2026年度(3年後期)'!$B$5:$N$207,COLUMN('2026年度(3年後期)'!$I$5)+1,0)&"" | I21: =VLOOKUP($C2,'2026年度(4年後期)'!$B$5:$N$206,COLUMN('2026年度(4年後期)'!$I$5)+1,0)&"" | K21: =VLOOKUP($C2,'2026年度(助産後期)'!$B$5:$N$207,COLUMN('2026年度(助産後期)'!$I$5)+1,0)&"" | M21: =VLOOKUP($C2,'2026年度(M1後期)'!$B$5:$N$207,COLUMN('2026年度(M1後期)'!$I$5)+1,0)&"" | O21: =VLOOKUP($C2,'2026年度(M2後期)'!$B$5:$N$207,COLUMN('2026年度(M2後期)'!$I$5)+1,0)&"" | Q21: =VLOOKUP($C2,'2026年度(D1後期)'!$B$5:$N$207,COLUMN('2026年度(D1後期)'!$I$5)+1,0)&"" | S21: =VLOOKUP($C2,'2026年度(D23後期)'!$B$5:$N$207,COLUMN('2026年度(D23後期)'!$I$5)+1,0)&""
B22: 備 考
A23: ５時限（16：50～18：20） | B23: 科目名 | C23: =VLOOKUP($C2,'2026年度(1年後期)'!$B$5:$N$207,COLUMN('2026年度(1年後期)'!$K$5),0)&"" | E23: =VLOOKUP($C2,'2026年度(2年後期)'!$B$5:$N$207,COLUMN('2026年度(2年後期)'!$K$5),0)&"" | G23: =VLOOKUP($C2,'2026年度(3年後期)'!$B$5:$N$207,COLUMN('2026年度(3年後期)'!$K$5),0)&"" | I23: =VLOOKUP($C2,'2026年度(4年後期)'!$B$5:$N$206,COLUMN('2026年度(4年後期)'!$K$5),0)&"" | K23: =VLOOKUP($C2,'2026年度(助産後期)'!$B$5:$N$207,COLUMN('2026年度(助産後期)'!$K$5),0)&"" | M23: =VLOOKUP($C2,'2026年度(M1後期)'!$B$5:$N$207,COLUMN('2026年度(M1後期)'!$K$5),0)&"" | O23: =VLOOKUP($C2,'2026年度(M2後期)'!$B$5:$N$207,COLUMN('2026年度(M2後期)'!$K$5),0)&"" | Q23: =VLOOKUP($C2,'2026年度(D1後期)'!$B$5:$N$207,COLUMN('2026年度(D1後期)'!$K$5),0)&"" | S23: =VLOOKUP($C2,'2026年度(D23後期)'!$B$5:$N$207,COLUMN('2026年度(D23後期)'!$K$5),0)&"" | Z23: =A23 -> ５時限（16：50～18：20）
B24: 教 官 | C24: =IFERROR(VLOOKUP(C23,科目・教員!$A$2:$B$342,2,0),"") | E24: =IFERROR(VLOOKUP(E23,科目・教員!$A$2:$B$342,2,0),"") | G24: =IFERROR(VLOOKUP(G23,科目・教員!$A$2:$B$342,2,0),"") | I24: =IFERROR(VLOOKUP(I23,科目・教員!$A$2:$B$342,2,0),"") | K24: =IFERROR(VLOOKUP(K23,科目・教員!$A$2:$B$342,2,0),"") | M24: =IFERROR(VLOOKUP(M23,科目・教員!$A$2:$B$342,2,0),"") | O24: =IFERROR(VLOOKUP(O23,科目・教員!$A$2:$B$342,2,0),"") | Q24: =IFERROR(VLOOKUP(Q23,科目・教員!$A$2:$B$342,2,0),"") | S24: =IFERROR(VLOOKUP(S23,科目・教員!$A$2:$B$342,2,0),"")
B25: 使用教室 | C25: =VLOOKUP($C2,'2026年度(1年後期)'!$B$5:$N$207,COLUMN('2026年度(1年後期)'!$K$5)+1,0)&"" | E25: =VLOOKUP($C2,'2026年度(2年後期)'!$B$5:$N$207,COLUMN('2026年度(2年後期)'!$K$5)+1,0)&"" | G25: =VLOOKUP($C2,'2026年度(3年後期)'!$B$5:$N$207,COLUMN('2026年度(3年後期)'!$K$5)+1,0)&"" | I25: =VLOOKUP($C2,'2026年度(4年後期)'!$B$5:$N$206,COLUMN('2026年度(4年後期)'!$K$5)+1,0)&"" | K25: =VLOOKUP($C2,'2026年度(助産後期)'!$B$5:$N$207,COLUMN('2026年度(助産後期)'!$K$5)+1,0)&"" | M25: =VLOOKUP($C2,'2026年度(M1後期)'!$B$5:$N$207,COLUMN('2026年度(M1後期)'!$K$5)+1,0)&"" | O25: =VLOOKUP($C2,'2026年度(M2後期)'!$B$5:$N$207,COLUMN('2026年度(M2後期)'!$K$5)+1,0)&"" | Q25: =VLOOKUP($C2,'2026年度(D1後期)'!$B$5:$N$207,COLUMN('2026年度(D1後期)'!$K$5)+1,0)&"" | S25: =VLOOKUP($C2,'2026年度(D23後期)'!$B$5:$N$207,COLUMN('2026年度(D23後期)'!$K$5)+1,0)&""
B26: 備 考
C27: =C2+1 -> 46328 | U27: =C27 -> 46328 | AA27: 101 | AB27: 102 | AC27: 103 | AD27: 在宅実習室 | AE27: 成人実習室 | AF27: 講堂 | AG27: 201 | AH27: 202 | AI27: 203 | AJ27: 204 | AK27: 205 | AL27: 基礎実習室 | AM27: 母性・小児実習室 | AN27: 演習21 | AO27: 演習22 | AP27: 演習23 | AQ27: 演習24 | AR27: 演習25 | AS27: 演習26 | AT27: 演習27 | AU27: 演習28 | AV27: 演習29 | AW27: 301 | AX27: 302 | AY27: 303 | AZ27: 304 | BA27: 臨床１ | BB27: 臨床２ | BC27: LL1 | BD27: LL2 | BE27: 実験室 | BF27: 情報処理室 | BG27: 演習31 | BH27: 演習32 | BI27: セミナー室１ | BJ27: セミナー室２ | BK27: セミナー室3 | BL27: セミナー室4 | BM27: セミナー室5 | BN27: 大講義室 | BO27: アリーナ | BP27: 研修１ | BQ27: 研修３ | BR27: 研修４ | BS27: 研修５ | BT27: 研修６ | BU27: 研修７ | BV27: 視聴覚室
A28: １時限（09：20～10：50） | B28: 科目名 | C28: =VLOOKUP($C27,'2026年度(1年後期)'!$B$5:$N$207,COLUMN('2026年度(1年後期)'!$C$5),0)&"" -> 心と発達 | E28: =VLOOKUP($C27,'2026年度(2年後期)'!$B$5:$N$207,COLUMN('2026年度(2年後期)'!$C$5),0)&"" -> 英語Ⅳ | G28: =VLOOKUP($C27,'2026年度(3年後期)'!$B$5:$N$207,COLUMN('2026年度(3年後期)'!$C$5),0)&"" -> 領域別実習 | I28: =VLOOKUP($C27,'2026年度(4年後期)'!$B$5:$N$206,COLUMN('2026年度(4年後期)'!$C$5),0)&"" | K28: =VLOOKUP($C27,'2026年度(助産後期)'!$B$5:$N$207,COLUMN('2026年度(助産後期)'!$C$5),0)&"" -> 助産学実習Ⅰ(追実習) | M28: =VLOOKUP($C27,'2026年度(M1後期)'!$B$5:$N$207,COLUMN('2026年度(M1後期)'!$C$5),0)&"" -> D論文審査会（12月申請） | O28: =VLOOKUP($C27,'2026年度(M2後期)'!$B$5:$N$207,COLUMN('2026年度(M2後期)'!$C$5),0)&"" -> D論文審査会（12月申請） | Q28: =VLOOKUP($C27,'2026年度(D1後期)'!$B$5:$N$207,COLUMN('2026年度(D1後期)'!$C$5),0)&"" -> D論文審査会（12月申請） | S28: =VLOOKUP($C27,'2026年度(D23後期)'!$B$5:$N$207,COLUMN('2026年度(D23後期)'!$C$5),0)&"" -> D論文審査会（12月申請） | V28: ９：0０～17：00 | Z28: =A28 -> １時限（09：20～10：50） | AA28: 心と発達 | AG28: 英語Ⅳ | AH28: 成人看護学実習Ⅱ | AI28: 成人看護学実習Ⅱ | AJ28: 成人看護学実習Ⅱ | AM28: 母性看護学実習（自主練）
B29: 教 官 | C29: =IFERROR(VLOOKUP(C28,科目・教員!$A$2:$B$342,2,0),"") -> 松本 聡子 | E29: =IFERROR(VLOOKUP(E28,科目・教員!$A$2:$B$342,2,0),"") -> ﾊﾟｳﾗ･ﾍﾞﾙｳﾞｧﾝｹﾙ | G29: =IFERROR(VLOOKUP(G28,科目・教員!$A$2:$B$342,2,0),"") | I29: =IFERROR(VLOOKUP(I28,科目・教員!$A$2:$B$342,2,0),"") | K29: =IFERROR(VLOOKUP(K28,科目・教員!$A$2:$B$342,2,0),"") | M29: =IFERROR(VLOOKUP(M28,科目・教員!$A$2:$B$342,2,0),"") | O29: =IFERROR(VLOOKUP(O28,科目・教員!$A$2:$B$342,2,0),"") | Q29: =IFERROR(VLOOKUP(Q28,科目・教員!$A$2:$B$342,2,0),"") | S29: =IFERROR(VLOOKUP(S28,科目・教員!$A$2:$B$342,2,0),"") | V29: 母性看護学実習（自主練）
B30: 使用教室 | C30: =VLOOKUP($C27,'2026年度(1年後期)'!$B$5:$N$207,COLUMN('2026年度(1年後期)'!$C$5)+1,0)&"" -> 101 | E30: =VLOOKUP($C27,'2026年度(2年後期)'!$B$5:$N$207,COLUMN('2026年度(2年後期)'!$C$5)+1,0)&"" -> 201 | G30: =VLOOKUP($C27,'2026年度(3年後期)'!$B$5:$N$207,COLUMN('2026年度(3年後期)'!$C$5)+1,0)&"" -> 成人Ⅱ:202･203･204 | I30: =VLOOKUP($C27,'2026年度(4年後期)'!$B$5:$N$206,COLUMN('2026年度(4年後期)'!$C$5)+1,0)&"" | K30: =VLOOKUP($C27,'2026年度(助産後期)'!$B$5:$N$207,COLUMN('2026年度(助産後期)'!$C$5)+1,0)&"" | M30: =VLOOKUP($C27,'2026年度(M1後期)'!$B$5:$N$207,COLUMN('2026年度(M1後期)'!$C$5)+1,0)&"" -> 301･302 | O30: =VLOOKUP($C27,'2026年度(M2後期)'!$B$5:$N$207,COLUMN('2026年度(M2後期)'!$C$5)+1,0)&"" -> 301･302 | Q30: =VLOOKUP($C27,'2026年度(D1後期)'!$B$5:$N$207,COLUMN('2026年度(D1後期)'!$C$5)+1,0)&"" -> 301･302 | S30: =VLOOKUP($C27,'2026年度(D23後期)'!$B$5:$N$207,COLUMN('2026年度(D23後期)'!$C$5)+1,0)&"" -> 301･302 | V30: 齋藤先生
B31: 備 考 | C31: 非常勤講師控室C | E31: 非常勤講師控室A | V31: 母性小児看護実習室
A32: ２時限（11：00～12：30） | B32: 科目名 | C32: =VLOOKUP($C27,'2026年度(1年後期)'!$B$5:$N$207,COLUMN('2026年度(1年後期)'!$E$5),0)&"" -> 生活援助論Ⅱ | E32: =VLOOKUP($C27,'2026年度(2年後期)'!$B$5:$N$207,COLUMN('2026年度(2年後期)'!$E$5),0)&"" -> 英語Ⅳ | G32: =VLOOKUP($C27,'2026年度(3年後期)'!$B$5:$N$207,COLUMN('2026年度(3年後期)'!$E$5),0)&"" -> 領域別実習 | I32: =VLOOKUP($C27,'2026年度(4年後期)'!$B$5:$N$206,COLUMN('2026年度(4年後期)'!$E$5),0)&"" | K32: =VLOOKUP($C27,'2026年度(助産後期)'!$B$5:$N$207,COLUMN('2026年度(助産後期)'!$E$5),0)&"" -> 助産学実習Ⅰ(追実習) | M32: =VLOOKUP($C27,'2026年度(M1後期)'!$B$5:$N$207,COLUMN('2026年度(M1後期)'!$E$5),0)&"" -> D論文審査会（12月申請） | O32: =VLOOKUP($C27,'2026年度(M2後期)'!$B$5:$N$207,COLUMN('2026年度(M2後期)'!$E$5),0)&"" -> D論文審査会（12月申請） | Q32: =VLOOKUP($C27,'2026年度(D1後期)'!$B$5:$N$207,COLUMN('2026年度(D1後期)'!$E$5),0)&"" -> D論文審査会（12月申請） | S32: =VLOOKUP($C27,'2026年度(D23後期)'!$B$5:$N$207,COLUMN('2026年度(D23後期)'!$E$5),0)&"" -> D論文審査会（12月申請） | Z32: =A32 -> ２時限（11：00～12：30） | AA32: 生活援助論Ⅱ | AG32: 英語Ⅳ | AH32: 成人看護学実習Ⅱ | AI32: 成人看護学実習Ⅱ | AJ32: 成人看護学実習Ⅱ | AM32: 母性看護学実習（自主練）
B33: 教 官 | C33: =IFERROR(VLOOKUP(C32,科目・教員!$A$2:$B$342,2,0),"") -> 森下 純子 | E33: =IFERROR(VLOOKUP(E32,科目・教員!$A$2:$B$342,2,0),"") -> ﾊﾟｳﾗ･ﾍﾞﾙｳﾞｧﾝｹﾙ | G33: =IFERROR(VLOOKUP(G32,科目・教員!$A$2:$B$342,2,0),"") | I33: =IFERROR(VLOOKUP(I32,科目・教員!$A$2:$B$342,2,0),"") | K33: =IFERROR(VLOOKUP(K32,科目・教員!$A$2:$B$342,2,0),"") | M33: =IFERROR(VLOOKUP(M32,科目・教員!$A$2:$B$342,2,0),"") | O33: =IFERROR(VLOOKUP(O32,科目・教員!$A$2:$B$342,2,0),"") | Q33: =IFERROR(VLOOKUP(Q32,科目・教員!$A$2:$B$342,2,0),"") | S33: =IFERROR(VLOOKUP(S32,科目・教員!$A$2:$B$342,2,0),"")
B34: 使用教室 | C34: =VLOOKUP($C27,'2026年度(1年後期)'!$B$5:$N$207,COLUMN('2026年度(1年後期)'!$E$5)+1,0)&"" -> 101 | E34: =VLOOKUP($C27,'2026年度(2年後期)'!$B$5:$N$207,COLUMN('2026年度(2年後期)'!$E$5)+1,0)&"" -> 201 | G34: =VLOOKUP($C27,'2026年度(3年後期)'!$B$5:$N$207,COLUMN('2026年度(3年後期)'!$E$5)+1,0)&"" -> 成人Ⅱ:202･203･204 | I34: =VLOOKUP($C27,'2026年度(4年後期)'!$B$5:$N$206,COLUMN('2026年度(4年後期)'!$E$5)+1,0)&"" | K34: =VLOOKUP($C27,'2026年度(助産後期)'!$B$5:$N$207,COLUMN('2026年度(助産後期)'!$E$5)+1,0)&"" | M34: =VLOOKUP($C27,'2026年度(M1後期)'!$B$5:$N$207,COLUMN('2026年度(M1後期)'!$E$5)+1,0)&"" -> 301･302 | O34: =VLOOKUP($C27,'2026年度(M2後期)'!$B$5:$N$207,COLUMN('2026年度(M2後期)'!$E$5)+1,0)&"" -> 301･302 | Q34: =VLOOKUP($C27,'2026年度(D1後期)'!$B$5:$N$207,COLUMN('2026年度(D1後期)'!$E$5)+1,0)&"" -> 301･302 | S34: =VLOOKUP($C27,'2026年度(D23後期)'!$B$5:$N$207,COLUMN('2026年度(D23後期)'!$E$5)+1,0)&"" -> 301･302
B35: 備 考 | E35: 非常勤講師控室A
A36: 昼休み（12：30～13：30） | B36: 活動名 | Z36: =A36 -> 昼休み（12：30～13：30） | AM36: 母性看護学実習（自主練）
B37: 責任者
B38: 使用教室
B39: 備 考
A40: ３時限（13：30～15：00） | B40: 科目名 | C40: =VLOOKUP($C27,'2026年度(1年後期)'!$B$5:$N$207,COLUMN('2026年度(1年後期)'!$G$5),0)&"" -> 疫学・保健統計学Ⅱ | E40: =VLOOKUP($C27,'2026年度(2年後期)'!$B$5:$N$207,COLUMN('2026年度(2年後期)'!$G$5),0)&"" -> 英語S | G40: =VLOOKUP($C27,'2026年度(3年後期)'!$B$5:$N$207,COLUMN('2026年度(3年後期)'!$G$5),0)&"" -> 領域別実習 | I40: =VLOOKUP($C27,'2026年度(4年後期)'!$B$5:$N$206,COLUMN('2026年度(4年後期)'!$G$5),0)&"" | K40: =VLOOKUP($C27,'2026年度(助産後期)'!$B$5:$N$207,COLUMN('2026年度(助産後期)'!$G$5),0)&"" -> 助産学実習Ⅰ(追実習) | M40: =VLOOKUP($C27,'2026年度(M1後期)'!$B$5:$N$207,COLUMN('2026年度(M1後期)'!$G$5),0)&"" -> 看護理論 | O40: =VLOOKUP($C27,'2026年度(M2後期)'!$B$5:$N$207,COLUMN('2026年度(M2後期)'!$G$5),0)&"" -> 特別研究 | Q40: =VLOOKUP($C27,'2026年度(D1後期)'!$B$5:$N$207,COLUMN('2026年度(D1後期)'!$G$5),0)&"" -> 量的看護学研究法 | S40: =VLOOKUP($C27,'2026年度(D23後期)'!$B$5:$N$207,COLUMN('2026年度(D23後期)'!$G$5),0)&"" -> 特別研究 | Z40: =A40 -> ３時限（13：30～15：00） | AA40: 疫学･保健統計学Ⅱ | AH40: 成人看護学実習Ⅱ | AI40: 成人看護学実習Ⅱ | AJ40: 成人看護学実習Ⅱ | AM40: 母性看護学実習（自主練） | AZ40: 英語S | BB40: 量的看護学研究法
...

Sheet 2026年12月
A1: 46357 | C1: １年 | E1: ２年 | G1: ３年 | I1: ４年 | K1: 助産 | M1: 研究課程部 Ｍ１ | O1: 研究課程部 Ｍ２ | Q1: 研究課程部 Ｄ１ | S1: 研究課程部 Ｄ２３ | U1: =A1 -> 46357 | V1: 授業外その他教室等管理スケジュール | AA1: １階 | AG1: ２階 | AW1: ３階 | BI1: ４階 | BN1: 体育棟 | BP1: 研修棟
C2: =A1 -> 46357 | U2: =C2 -> 46357 | AA2: 101 | AB2: 102 | AC2: 103 | AD2: 在宅実習室 | AE2: 成人実習室 | AF2: 講堂 | AG2: 201 | AH2: 202 | AI2: 203 | AJ2: 204 | AK2: 205 | AL2: 基礎実習室 | AM2: 母性・小児実習室 | AN2: 演習21 | AO2: 演習22 | AP2: 演習23 | AQ2: 演習24 | AR2: 演習25 | AS2: 演習26 | AT2: 演習27 | AU2: 演習28 | AV2: 演習29 | AW2: 301 | AX2: 302 | AY2: 303 | AZ2: 304 | BA2: 臨床１ | BB2: 臨床２ | BC2: LL1 | BD2: LL2 | BE2: 実験室 | BF2: 情報処理室 | BG2: 演習31 | BH2: 演習32 | BI2: セミナー室１ | BJ2: セミナー室２ | BK2: セミナー室3 | BL2: セミナー室4 | BM2: セミナー室5 | BN2: 大講義室 | BO2: アリーナ | BP2: 研修１ | BQ2: 研修３ | BR2: 研修４ | BS2: 研修５ | BT2: 研修６ | BU2: 研修７ | BV2: 視聴覚室
A3: １時限（09：20～10：50） | B3: 科目名 | C3: =VLOOKUP($C2,'2026年度(1年後期)'!$B$5:$N$207,COLUMN('2026年度(1年後期)'!$C$5),0)&"" -> 日本人論 | E3: =VLOOKUP($C2,'2026年度(2年後期)'!$B$5:$N$207,COLUMN('2026年度(2年後期)'!$C$5),0)&"" -> 基礎看護学実習Ⅱ | G3: =VLOOKUP($C2,'2026年度(3年後期)'!$B$5:$N$207,COLUMN('2026年度(3年後期)'!$C$5),0)&"" -> 領域別実習 | I3: =VLOOKUP($C2,'2026年度(4年後期)'!$B$5:$N$206,COLUMN('2026年度(4年後期)'!$C$5),0)&"" -> 総合学習 | K3: =VLOOKUP($C2,'2026年度(助産後期)'!$B$5:$N$207,COLUMN('2026年度(助産後期)'!$C$5),0)&"" | M3: =VLOOKUP($C2,'2026年度(M1後期)'!$B$5:$N$207,COLUMN('2026年度(M1後期)'!$C$5),0)&"" -> 国際看護学演習A-Ⅰ 成育看護学演習A-Ⅰ・Ⅳ(小児) 感染症学特論 感染症学演習 精神看護学演習A-Ⅱ | O3: =VLOOKUP($C2,'2026年度(M2後期)'!$B$5:$N$207,COLUMN('2026年度(M2後期)'!$C$5),0)&"" -> 特別研究 | Q3: =VLOOKUP($C2,'2026年度(D1後期)'!$B$5:$N$207,COLUMN('2026年度(D1後期)'!$C$5),0)&"" -> 成育看護学演習Ｂ 感染管理看護学演習Ｂ 成人看護学演習Ｂ 国際看護学演習Ｂ | S3: =VLOOKUP($C2,'2026年度(D23後期)'!$B$5:$N$207,COLUMN('2026年度(D23後期)'!$C$5),0)&"" -> 特別研究 | U3: 1～4限 | Y3: 9：00～17：00 | Z3: =A3 -> １時限（09：20～10：50） | AA3: 日本人論 | AF3: 卒業記念パーティ演奏練習 | AG3: 母性看護学実習 | AM3: 母性看護学実習 | AW3: 成人看護学実習Ⅰ補習 | BB3: 精神看護学演習A－Ⅱ | BN3: 総合学習
B4: 教 官 | C4: =IFERROR(VLOOKUP(C3,科目・教員!$A$2:$B$342,2,0),"") -> 川出 龍一 | E4: =IFERROR(VLOOKUP(E3,科目・教員!$A$2:$B$342,2,0),"") -> 森下 純子 | G4: =IFERROR(VLOOKUP(G3,科目・教員!$A$2:$B$342,2,0),"") | I4: =IFERROR(VLOOKUP(I3,科目・教員!$A$2:$B$342,2,0),"") | K4: =IFERROR(VLOOKUP(K3,科目・教員!$A$2:$B$342,2,0),"") | M4: =IFERROR(VLOOKUP(M3,科目・教員!$A$2:$B$342,2,0),"") | O4: =IFERROR(VLOOKUP(O3,科目・教員!$A$2:$B$342,2,0),"") | Q4: =IFERROR(VLOOKUP(Q3,科目・教員!$A$2:$B$342,2,0),"") | S4: =IFERROR(VLOOKUP(S3,科目・教員!$A$2:$B$342,2,0),"") | U4: 成人看護学実習Ⅰ補習 | Y4: 卒業記念パーティ
B5: 使用教室 | C5: =VLOOKUP($C2,'2026年度(1年後期)'!$B$5:$N$207,COLUMN('2026年度(1年後期)'!$C$5)+1,0)&"" -> 101 | E5: =VLOOKUP($C2,'2026年度(2年後期)'!$B$5:$N$207,COLUMN('2026年度(2年後期)'!$C$5)+1,0)&"" | G5: =VLOOKUP($C2,'2026年度(3年後期)'!$B$5:$N$207,COLUMN('2026年度(3年後期)'!$C$5)+1,0)&"" -> 母性:201･母小実 | I5: =VLOOKUP($C2,'2026年度(4年後期)'!$B$5:$N$206,COLUMN('2026年度(4年後期)'!$C$5)+1,0)&"" -> 大講義室 | K5: =VLOOKUP($C2,'2026年度(助産後期)'!$B$5:$N$207,COLUMN('2026年度(助産後期)'!$C$5)+1,0)&"" | M5: =VLOOKUP($C2,'2026年度(M1後期)'!$B$5:$N$207,COLUMN('2026年度(M1後期)'!$C$5)+1,0)&"" -> 精神：臨床講義室２ | O5: =VLOOKUP($C2,'2026年度(M2後期)'!$B$5:$N$207,COLUMN('2026年度(M2後期)'!$C$5)+1,0)&"" | Q5: =VLOOKUP($C2,'2026年度(D1後期)'!$B$5:$N$207,COLUMN('2026年度(D1後期)'!$C$5)+1,0)&"" | S5: =VLOOKUP($C2,'2026年度(D23後期)'!$B$5:$N$207,COLUMN('2026年度(D23後期)'!$C$5)+1,0)&"" | U5: 301教室 | Y5: 演奏練習
B6: 備 考 | C6: 非常勤講師控室C | U6: 杉山先生 | Y6: 講堂
A7: ２時限（11：00～12：30） | B7: 科目名 | C7: =VLOOKUP($C2,'2026年度(1年後期)'!$B$5:$N$207,COLUMN('2026年度(1年後期)'!$E$5),0)&"" -> 知の探求 | E7: =VLOOKUP($C2,'2026年度(2年後期)'!$B$5:$N$207,COLUMN('2026年度(2年後期)'!$E$5),0)&"" -> 基礎看護学実習Ⅱ | G7: =VLOOKUP($C2,'2026年度(3年後期)'!$B$5:$N$207,COLUMN('2026年度(3年後期)'!$E$5),0)&"" -> 領域別実習 | I7: =VLOOKUP($C2,'2026年度(4年後期)'!$B$5:$N$206,COLUMN('2026年度(4年後期)'!$E$5),0)&"" -> 総合学習 | K7: =VLOOKUP($C2,'2026年度(助産後期)'!$B$5:$N$207,COLUMN('2026年度(助産後期)'!$E$5),0)&"" | M7: =VLOOKUP($C2,'2026年度(M1後期)'!$B$5:$N$207,COLUMN('2026年度(M1後期)'!$E$5),0)&"" -> 国際看護学演習A-Ⅰ 成育看護学演習A-Ⅰ・Ⅳ（小児） 感染症学特論 感染症学演習 精神看護学演習A-Ⅱ | O7: =VLOOKUP($C2,'2026年度(M2後期)'!$B$5:$N$207,COLUMN('2026年度(M2後期)'!$E$5),0)&"" -> 特別研究 | Q7: =VLOOKUP($C2,'2026年度(D1後期)'!$B$5:$N$207,COLUMN('2026年度(D1後期)'!$E$5),0)&"" -> 成育看護学演習Ｂ 感染管理看護学演習Ｂ 成人看護学演習Ｂ 国際看護学演習Ｂ | S7: =VLOOKUP($C2,'2026年度(D23後期)'!$B$5:$N$207,COLUMN('2026年度(D23後期)'!$E$5),0)&"" -> 特別研究 | Z7: =A7 -> ２時限（11：00～12：30） | AA7: 知の探求 | AF7: 卒業記念パーティ演奏練習 | AG7: 母性看護学実習 | AM7: 母性看護学実習 | AW7: 成人看護学実習Ⅰ補習 | BB7: 精神看護学演習A－Ⅱ | BN7: 総合学習
B8: 教 官 | C8: =IFERROR(VLOOKUP(C7,科目・教員!$A$2:$B$342,2,0),"") -> 須藤 恭子 | E8: =IFERROR(VLOOKUP(E7,科目・教員!$A$2:$B$342,2,0),"") -> 森下 純子 | G8: =IFERROR(VLOOKUP(G7,科目・教員!$A$2:$B$342,2,0),"") | I8: =IFERROR(VLOOKUP(I7,科目・教員!$A$2:$B$342,2,0),"") | K8: =IFERROR(VLOOKUP(K7,科目・教員!$A$2:$B$342,2,0),"") | M8: =IFERROR(VLOOKUP(M7,科目・教員!$A$2:$B$342,2,0),"") | O8: =IFERROR(VLOOKUP(O7,科目・教員!$A$2:$B$342,2,0),"") | Q8: =IFERROR(VLOOKUP(Q7,科目・教員!$A$2:$B$342,2,0),"") | S8: =IFERROR(VLOOKUP(S7,科目・教員!$A$2:$B$342,2,0),"")
B9: 使用教室 | C9: =VLOOKUP($C2,'2026年度(1年後期)'!$B$5:$N$207,COLUMN('2026年度(1年後期)'!$E$5)+1,0)&"" -> 101 | E9: =VLOOKUP($C2,'2026年度(2年後期)'!$B$5:$N$207,COLUMN('2026年度(2年後期)'!$E$5)+1,0)&"" | G9: =VLOOKUP($C2,'2026年度(3年後期)'!$B$5:$N$207,COLUMN('2026年度(3年後期)'!$E$5)+1,0)&"" -> 母性:201･母小実 | I9: =VLOOKUP($C2,'2026年度(4年後期)'!$B$5:$N$206,COLUMN('2026年度(4年後期)'!$E$5)+1,0)&"" -> 大講義室 | K9: =VLOOKUP($C2,'2026年度(助産後期)'!$B$5:$N$207,COLUMN('2026年度(助産後期)'!$E$5)+1,0)&"" | M9: =VLOOKUP($C2,'2026年度(M1後期)'!$B$5:$N$207,COLUMN('2026年度(M1後期)'!$E$5)+1,0)&"" -> 精神：臨床講義室２ | O9: =VLOOKUP($C2,'2026年度(M2後期)'!$B$5:$N$207,COLUMN('2026年度(M2後期)'!$E$5)+1,0)&"" | Q9: =VLOOKUP($C2,'2026年度(D1後期)'!$B$5:$N$207,COLUMN('2026年度(D1後期)'!$E$5)+1,0)&"" | S9: =VLOOKUP($C2,'2026年度(D23後期)'!$B$5:$N$207,COLUMN('2026年度(D23後期)'!$E$5)+1,0)&""
B10: 備 考
A11: 昼休み（12：30～13：30） | B11: 活動名 | Z11: =A11 -> 昼休み（12：30～13：30） | AF11: 卒業記念パーティ演奏練習
B12: 責任者
B13: 使用教室
B14: 備 考
A15: ３時限（13：30～15：00） | B15: 科目名 | C15: =VLOOKUP($C2,'2026年度(1年後期)'!$B$5:$N$207,COLUMN('2026年度(1年後期)'!$G$5),0)&"" -> ジェンダー論 | E15: =VLOOKUP($C2,'2026年度(2年後期)'!$B$5:$N$207,COLUMN('2026年度(2年後期)'!$G$5),0)&"" -> 基礎看護学実習Ⅱ | G15: =VLOOKUP($C2,'2026年度(3年後期)'!$B$5:$N$207,COLUMN('2026年度(3年後期)'!$G$5),0)&"" -> 領域別実習 | I15: =VLOOKUP($C2,'2026年度(4年後期)'!$B$5:$N$206,COLUMN('2026年度(4年後期)'!$G$5),0)&"" | K15: =VLOOKUP($C2,'2026年度(助産後期)'!$B$5:$N$207,COLUMN('2026年度(助産後期)'!$G$5),0)&"" -> 助産管理論（山本先生） | M15: =VLOOKUP($C2,'2026年度(M1後期)'!$B$5:$N$207,COLUMN('2026年度(M1後期)'!$G$5),0)&"" -> がん看護学演習A-Ⅱ 成育看護学演習A-Ⅰ（小児） 感染症学特論 感染症学演習 | O15: =VLOOKUP($C2,'2026年度(M2後期)'!$B$5:$N$207,COLUMN('2026年度(M2後期)'!$G$5),0)&"" -> 特別研究 | Q15: =VLOOKUP($C2,'2026年度(D1後期)'!$B$5:$N$207,COLUMN('2026年度(D1後期)'!$G$5),0)&"" -> 量的看護学研究法 | S15: =VLOOKUP($C2,'2026年度(D23後期)'!$B$5:$N$207,COLUMN('2026年度(D23後期)'!$G$5),0)&"" -> 特別研究 | U15: 3～4限 | Z15: =A15 -> ３時限（13：30～15：00） | AA15: ジェンダー論 | AF15: 卒業記念パーティ演奏練習 | AG15: 母性看護学実習 | AM15: 母性看護学実習 | AW15: 成人看護学実習Ⅰ補習 | AZ15: 助産管理論 | BA15: 量的看護学研究法 | BB15: 精神看護学演習A－Ⅱ | BM15: D1坂口 | BN15: 政策医療看護論Ⅱ
B16: 教 官 | C16: =IFERROR(VLOOKUP(C15,科目・教員!$A$2:$B$342,2,0),"") -> 小島 優子 | E16: =IFERROR(VLOOKUP(E15,科目・教員!$A$2:$B$342,2,0),"") -> 森下 純子 | G16: =IFERROR(VLOOKUP(G15,科目・教員!$A$2:$B$342,2,0),"") | I16: =IFERROR(VLOOKUP(I15,科目・教員!$A$2:$B$342,2,0),"") | K16: =IFERROR(VLOOKUP(K15,科目・教員!$A$2:$B$342,2,0),"") | M16: =IFERROR(VLOOKUP(M15,科目・教員!$A$2:$B$342,2,0),"") | O16: =IFERROR(VLOOKUP(O15,科目・教員!$A$2:$B$342,2,0),"") | Q16: =IFERROR(VLOOKUP(Q15,科目・教員!$A$2:$B$342,2,0),"") -> 柏木 公一 | S16: =IFERROR(VLOOKUP(S15,科目・教員!$A$2:$B$342,2,0),"") | U16: 量的看護研究法
B17: 使用教室 | C17: =VLOOKUP($C2,'2026年度(1年後期)'!$B$5:$N$207,COLUMN('2026年度(1年後期)'!$G$5)+1,0)&"" -> 101 | E17: =VLOOKUP($C2,'2026年度(2年後期)'!$B$5:$N$207,COLUMN('2026年度(2年後期)'!$G$5)+1,0)&"" | G17: =VLOOKUP($C2,'2026年度(3年後期)'!$B$5:$N$207,COLUMN('2026年度(3年後期)'!$G$5)+1,0)&"" -> 母性:201･母小実 | I17: =VLOOKUP($C2,'2026年度(4年後期)'!$B$5:$N$206,COLUMN('2026年度(4年後期)'!$G$5)+1,0)&"" | K17: =VLOOKUP($C2,'2026年度(助産後期)'!$B$5:$N$207,COLUMN('2026年度(助産後期)'!$G$5)+1,0)&"" -> 304 | M17: =VLOOKUP($C2,'2026年度(M1後期)'!$B$5:$N$207,COLUMN('2026年度(M1後期)'!$G$5)+1,0)&"" -> 精神：臨床講義室２ | O17: =VLOOKUP($C2,'2026年度(M2後期)'!$B$5:$N$207,COLUMN('2026年度(M2後期)'!$G$5)+1,0)&"" | Q17: =VLOOKUP($C2,'2026年度(D1後期)'!$B$5:$N$207,COLUMN('2026年度(D1後期)'!$G$5)+1,0)&"" -> 臨床講義室１ | S17: =VLOOKUP($C2,'2026年度(D23後期)'!$B$5:$N$207,COLUMN('2026年度(D23後期)'!$G$5)+1,0)&"" | U17: D1坂口
B18: 備 考 | K18: 非常勤講師控室B | U18: セミナールーム5
A19: ４時限（15：10～16：40） | B19: 科目名 | C19: =VLOOKUP($C2,'2026年度(1年後期)'!$B$5:$N$207,COLUMN('2026年度(1年後期)'!$I$5),0)&"" -> 人体の構造と機能Ⅲ (桑名先生③) | E19: =VLOOKUP($C2,'2026年度(2年後期)'!$B$5:$N$207,COLUMN('2026年度(2年後期)'!$I$5),0)&"" -> 基礎看護学実習Ⅱ | G19: =VLOOKUP($C2,'2026年度(3年後期)'!$B$5:$N$207,COLUMN('2026年度(3年後期)'!$I$5),0)&"" -> 領域別実習 | I19: =VLOOKUP($C2,'2026年度(4年後期)'!$B$5:$N$206,COLUMN('2026年度(4年後期)'!$I$5),0)&"" | K19: =VLOOKUP($C2,'2026年度(助産後期)'!$B$5:$N$207,COLUMN('2026年度(助産後期)'!$I$5),0)&"" -> 助産管理論（山本先生） | M19: =VLOOKUP($C2,'2026年度(M1後期)'!$B$5:$N$207,COLUMN('2026年度(M1後期)'!$I$5),0)&"" -> がん看護学演習A-Ⅱ 成育看護学演習A-Ⅰ 感染症学特論 感染症学演習 | O19: =VLOOKUP($C2,'2026年度(M2後期)'!$B$5:$N$207,COLUMN('2026年度(M2後期)'!$I$5),0)&"" -> 特別研究 | Q19: =VLOOKUP($C2,'2026年度(D1後期)'!$B$5:$N$207,COLUMN('2026年度(D1後期)'!$I$5),0)&"" -> 量的看護学研究法 | S19: =VLOOKUP($C2,'2026年度(D23後期)'!$B$5:$N$207,COLUMN('2026年度(D23後期)'!$I$5),0)&"" -> 特別研究 | Z19: =A19 -> ４時限（15：10～16：40） | AA19: 人体の構造と機能Ⅲ | AF19: 卒業記念パーティ演奏練習 | AG19: 母性看護学実習 | AM19: 母性看護学実習 | AW19: 成人看護学実習Ⅰ補習 | AZ19: 助産管理論 | BA19: 量的看護学研究法 | BB19: 精神看護学演習A－Ⅱ | BM19: D1坂口
B20: 教 官 | C20: =IFERROR(VLOOKUP(C19,科目・教員!$A$2:$B$342,2,0),"") | E20: =IFERROR(VLOOKUP(E19,科目・教員!$A$2:$B$342,2,0),"") -> 森下 純子 | G20: =IFERROR(VLOOKUP(G19,科目・教員!$A$2:$B$342,2,0),"") | I20: =IFERROR(VLOOKUP(I19,科目・教員!$A$2:$B$342,2,0),"") | K20: =IFERROR(VLOOKUP(K19,科目・教員!$A$2:$B$342,2,0),"") | M20: =IFERROR(VLOOKUP(M19,科目・教員!$A$2:$B$342,2,0),"") | O20: =IFERROR(VLOOKUP(O19,科目・教員!$A$2:$B$342,2,0),"") | Q20: =IFERROR(VLOOKUP(Q19,科目・教員!$A$2:$B$342,2,0),"") -> 柏木 公一 | S20: =IFERROR(VLOOKUP(S19,科目・教員!$A$2:$B$342,2,0),"")
B21: 使用教室 | C21: =VLOOKUP($C2,'2026年度(1年後期)'!$B$5:$N$207,COLUMN('2026年度(1年後期)'!$I$5)+1,0)&"" -> 101 | E21: =VLOOKUP($C2,'2026年度(2年後期)'!$B$5:$N$207,COLUMN('2026年度(2年後期)'!$I$5)+1,0)&"" | G21: =VLOOKUP($C2,'2026年度(3年後期)'!$B$5:$N$207,COLUMN('2026年度(3年後期)'!$I$5)+1,0)&"" -> 母性:201･母小実 | I21: =VLOOKUP($C2,'2026年度(4年後期)'!$B$5:$N$206,COLUMN('2026年度(4年後期)'!$I$5)+1,0)&"" | K21: =VLOOKUP($C2,'2026年度(助産後期)'!$B$5:$N$207,COLUMN('2026年度(助産後期)'!$I$5)+1,0)&"" -> 304 | M21: =VLOOKUP($C2,'2026年度(M1後期)'!$B$5:$N$207,COLUMN('2026年度(M1後期)'!$I$5)+1,0)&"" -> 精神：臨床講義室２ | O21: =VLOOKUP($C2,'2026年度(M2後期)'!$B$5:$N$207,COLUMN('2026年度(M2後期)'!$I$5)+1,0)&"" | Q21: =VLOOKUP($C2,'2026年度(D1後期)'!$B$5:$N$207,COLUMN('2026年度(D1後期)'!$I$5)+1,0)&"" -> 臨床講義室１ | S21: =VLOOKUP($C2,'2026年度(D23後期)'!$B$5:$N$207,COLUMN('2026年度(D23後期)'!$I$5)+1,0)&""
B22: 備 考 | C22: 非常勤講師控室A | K22: 非常勤講師控室B
A23: ５時限（16：50～18：20） | B23: 科目名 | C23: =VLOOKUP($C2,'2026年度(1年後期)'!$B$5:$N$207,COLUMN('2026年度(1年後期)'!$K$5),0)&"" | E23: =VLOOKUP($C2,'2026年度(2年後期)'!$B$5:$N$207,COLUMN('2026年度(2年後期)'!$K$5),0)&"" | G23: =VLOOKUP($C2,'2026年度(3年後期)'!$B$5:$N$207,COLUMN('2026年度(3年後期)'!$K$5),0)&"" | I23: =VLOOKUP($C2,'2026年度(4年後期)'!$B$5:$N$206,COLUMN('2026年度(4年後期)'!$K$5),0)&"" | K23: =VLOOKUP($C2,'2026年度(助産後期)'!$B$5:$N$207,COLUMN('2026年度(助産後期)'!$K$5),0)&"" | M23: =VLOOKUP($C2,'2026年度(M1後期)'!$B$5:$N$207,COLUMN('2026年度(M1後期)'!$K$5),0)&"" | O23: =VLOOKUP($C2,'2026年度(M2後期)'!$B$5:$N$207,COLUMN('2026年度(M2後期)'!$K$5),0)&"" | Q23: =VLOOKUP($C2,'2026年度(D1後期)'!$B$5:$N$207,COLUMN('2026年度(D1後期)'!$K$5),0)&"" | S23: =VLOOKUP($C2,'2026年度(D23後期)'!$B$5:$N$207,COLUMN('2026年度(D23後期)'!$K$5),0)&"" | Z23: =A23 -> ５時限（16：50～18：20） | AF23: 卒業記念パーティ演奏練習
B24: 教 官 | C24: =IFERROR(VLOOKUP(C23,科目・教員!$A$2:$B$342,2,0),"") | E24: =IFERROR(VLOOKUP(E23,科目・教員!$A$2:$B$342,2,0),"") | G24: =IFERROR(VLOOKUP(G23,科目・教員!$A$2:$B$342,2,0),"") | I24: =IFERROR(VLOOKUP(I23,科目・教員!$A$2:$B$342,2,0),"") | K24: =IFERROR(VLOOKUP(K23,科目・教員!$A$2:$B$342,2,0),"") | M24: =IFERROR(VLOOKUP(M23,科目・教員!$A$2:$B$342,2,0),"") | O24: =IFERROR(VLOOKUP(O23,科目・教員!$A$2:$B$342,2,0),"") | Q24: =IFERROR(VLOOKUP(Q23,科目・教員!$A$2:$B$342,2,0),"") | S24: =IFERROR(VLOOKUP(S23,科目・教員!$A$2:$B$342,2,0),"")
B25: 使用教室 | C25: =VLOOKUP($C2,'2026年度(1年後期)'!$B$5:$N$207,COLUMN('2026年度(1年後期)'!$K$5)+1,0)&"" | E25: =VLOOKUP($C2,'2026年度(2年後期)'!$B$5:$N$207,COLUMN('2026年度(2年後期)'!$K$5)+1,0)&"" | G25: =VLOOKUP($C2,'2026年度(3年後期)'!$B$5:$N$207,COLUMN('2026年度(3年後期)'!$K$5)+1,0)&"" | I25: =VLOOKUP($C2,'2026年度(4年後期)'!$B$5:$N$206,COLUMN('2026年度(4年後期)'!$K$5)+1,0)&"" | K25: =VLOOKUP($C2,'2026年度(助産後期)'!$B$5:$N$207,COLUMN('2026年度(助産後期)'!$K$5)+1,0)&"" | M25: =VLOOKUP($C2,'2026年度(M1後期)'!$B$5:$N$207,COLUMN('2026年度(M1後期)'!$K$5)+1,0)&"" | O25: =VLOOKUP($C2,'2026年度(M2後期)'!$B$5:$N$207,COLUMN('2026年度(M2後期)'!$K$5)+1,0)&"" | Q25: =VLOOKUP($C2,'2026年度(D1後期)'!$B$5:$N$207,COLUMN('2026年度(D1後期)'!$K$5)+1,0)&"" | S25: =VLOOKUP($C2,'2026年度(D23後期)'!$B$5:$N$207,COLUMN('2026年度(D23後期)'!$K$5)+1,0)&""
B26: 備 考
C27: =C2+1 -> 46358 | U27: =C27 -> 46358 | AA27: 101 | AB27: 102 | AC27: 103 | AD27: 在宅実習室 | AE27: 成人実習室 | AF27: 講堂 | AG27: 201 | AH27: 202 | AI27: 203 | AJ27: 204 | AK27: 205 | AL27: 基礎実習室 | AM27: 母性・小児実習室 | AN27: 演習21 | AO27: 演習22 | AP27: 演習23 | AQ27: 演習24 | AR27: 演習25 | AS27: 演習26 | AT27: 演習27 | AU27: 演習28 | AV27: 演習29 | AW27: 301 | AX27: 302 | AY27: 303 | AZ27: 304 | BA27: 臨床１ | BB27: 臨床２ | BC27: LL1 | BD27: LL2 | BE27: 実験室 | BF27: 情報処理室 | BG27: 演習31 | BH27: 演習32 | BI27: セミナー室１ | BJ27: セミナー室２ | BK27: セミナー室3 | BL27: セミナー室4 | BM27: セミナー室5 | BN27: 大講義室 | BO27: アリーナ | BP27: 研修１ | BQ27: 研修３ | BR27: 研修４ | BS27: 研修５ | BT27: 研修６ | BU27: 研修７ | BV27: 視聴覚室
A28: １時限（09：20～10：50） | B28: 科目名 | C28: =VLOOKUP($C27,'2026年度(1年後期)'!$B$5:$N$207,COLUMN('2026年度(1年後期)'!$C$5),0)&"" -> 疫学・保健統計学Ⅱ | E28: =VLOOKUP($C27,'2026年度(2年後期)'!$B$5:$N$207,COLUMN('2026年度(2年後期)'!$C$5),0)&"" -> 基礎看護学実習Ⅱ | G28: =VLOOKUP($C27,'2026年度(3年後期)'!$B$5:$N$207,COLUMN('2026年度(3年後期)'!$C$5),0)&"" -> 領域別実習 | I28: =VLOOKUP($C27,'2026年度(4年後期)'!$B$5:$N$206,COLUMN('2026年度(4年後期)'!$C$5),0)&"" | K28: =VLOOKUP($C27,'2026年度(助産後期)'!$B$5:$N$207,COLUMN('2026年度(助産後期)'!$C$5),0)&"" | M28: =VLOOKUP($C27,'2026年度(M1後期)'!$B$5:$N$207,COLUMN('2026年度(M1後期)'!$C$5),0)&"" -> 看護情報・管理学演習A-Ⅰ 成育看護学演習A-Ⅳ（母性） | O28: =VLOOKUP($C27,'2026年度(M2後期)'!$B$5:$N$207,COLUMN('2026年度(M2後期)'!$C$5),0)&"" -> 特別研究 | Q28: =VLOOKUP($C27,'2026年度(D1後期)'!$B$5:$N$207,COLUMN('2026年度(D1後期)'!$C$5),0)&"" | S28: =VLOOKUP($C27,'2026年度(D23後期)'!$B$5:$N$207,COLUMN('2026年度(D23後期)'!$C$5),0)&"" -> 特別研究 | V28: ９：0０～17：00 | Z28: =A28 -> １時限（09：20～10：50） | AA28: 疫学･保健統計学Ⅱ | AG28: 母性看護学実習 | AM28: 母性看護学実習（自主練）
B29: 教 官 | C29: =IFERROR(VLOOKUP(C28,科目・教員!$A$2:$B$342,2,0),"") -> 柏木 公一 | E29: =IFERROR(VLOOKUP(E28,科目・教員!$A$2:$B$342,2,0),"") -> 森下 純子 | G29: =IFERROR(VLOOKUP(G28,科目・教員!$A$2:$B$342,2,0),"") | I29: =IFERROR(VLOOKUP(I28,科目・教員!$A$2:$B$342,2,0),"") | K29: =IFERROR(VLOOKUP(K28,科目・教員!$A$2:$B$342,2,0),"") | M29: =IFERROR(VLOOKUP(M28,科目・教員!$A$2:$B$342,2,0),"") | O29: =IFERROR(VLOOKUP(O28,科目・教員!$A$2:$B$342,2,0),"") | Q29: =IFERROR(VLOOKUP(Q28,科目・教員!$A$2:$B$342,2,0),"") | S29: =IFERROR(VLOOKUP(S28,科目・教員!$A$2:$B$342,2,0),"") | V29: 母性看護学実習（自主練）
B30: 使用教室 | C30: =VLOOKUP($C27,'2026年度(1年後期)'!$B$5:$N$207,COLUMN('2026年度(1年後期)'!$C$5)+1,0)&"" -> 101 | E30: =VLOOKUP($C27,'2026年度(2年後期)'!$B$5:$N$207,COLUMN('2026年度(2年後期)'!$C$5)+1,0)&"" | G30: =VLOOKUP($C27,'2026年度(3年後期)'!$B$5:$N$207,COLUMN('2026年度(3年後期)'!$C$5)+1,0)&"" -> 母性:201 | I30: =VLOOKUP($C27,'2026年度(4年後期)'!$B$5:$N$206,COLUMN('2026年度(4年後期)'!$C$5)+1,0)&"" | K30: =VLOOKUP($C27,'2026年度(助産後期)'!$B$5:$N$207,COLUMN('2026年度(助産後期)'!$C$5)+1,0)&"" | M30: =VLOOKUP($C27,'2026年度(M1後期)'!$B$5:$N$207,COLUMN('2026年度(M1後期)'!$C$5)+1,0)&"" | O30: =VLOOKUP($C27,'2026年度(M2後期)'!$B$5:$N$207,COLUMN('2026年度(M2後期)'!$C$5)+1,0)&"" | Q30: =VLOOKUP($C27,'2026年度(D1後期)'!$B$5:$N$207,COLUMN('2026年度(D1後期)'!$C$5)+1,0)&"" | S30: =VLOOKUP($C27,'2026年度(D23後期)'!$B$5:$N$207,COLUMN('2026年度(D23後期)'!$C$5)+1,0)&"" | V30: 齋藤先生
B31: 備 考 | V31: 母性小児看護実習室
A32: ２時限（11：00～12：30） | B32: 科目名 | C32: =VLOOKUP($C27,'2026年度(1年後期)'!$B$5:$N$207,COLUMN('2026年度(1年後期)'!$E$5),0)&"" -> 疾病・病態論Ⅰ | E32: =VLOOKUP($C27,'2026年度(2年後期)'!$B$5:$N$207,COLUMN('2026年度(2年後期)'!$E$5),0)&"" -> 基礎看護学実習Ⅱ | G32: =VLOOKUP($C27,'2026年度(3年後期)'!$B$5:$N$207,COLUMN('2026年度(3年後期)'!$E$5),0)&"" -> 領域別実習 | I32: =VLOOKUP($C27,'2026年度(4年後期)'!$B$5:$N$206,COLUMN('2026年度(4年後期)'!$E$5),0)&"" | K32: =VLOOKUP($C27,'2026年度(助産後期)'!$B$5:$N$207,COLUMN('2026年度(助産後期)'!$E$5),0)&"" | M32: =VLOOKUP($C27,'2026年度(M1後期)'!$B$5:$N$207,COLUMN('2026年度(M1後期)'!$E$5),0)&"" -> 看護情報・管理学演習A-Ⅰ 成育看護学演習A-Ⅳ（母性） | O32: =VLOOKUP($C27,'2026年度(M2後期)'!$B$5:$N$207,COLUMN('2026年度(M2後期)'!$E$5),0)&"" -> 特別研究 | Q32: =VLOOKUP($C27,'2026年度(D1後期)'!$B$5:$N$207,COLUMN('2026年度(D1後期)'!$E$5),0)&"" | S32: =VLOOKUP($C27,'2026年度(D23後期)'!$B$5:$N$207,COLUMN('2026年度(D23後期)'!$E$5),0)&"" -> 特別研究 | Z32: =A32 -> ２時限（11：00～12：30） | AA32: 疾病･病態論Ⅰ | AG32: 母性看護学実習 | AM32: 母性看護学実習（自主練）
B33: 教 官 | C33: =IFERROR(VLOOKUP(C32,科目・教員!$A$2:$B$342,2,0),"") -> 水野 正之 | E33: =IFERROR(VLOOKUP(E32,科目・教員!$A$2:$B$342,2,0),"") -> 森下 純子 | G33: =IFERROR(VLOOKUP(G32,科目・教員!$A$2:$B$342,2,0),"") | I33: =IFERROR(VLOOKUP(I32,科目・教員!$A$2:$B$342,2,0),"") | K33: =IFERROR(VLOOKUP(K32,科目・教員!$A$2:$B$342,2,0),"") | M33: =IFERROR(VLOOKUP(M32,科目・教員!$A$2:$B$342,2,0),"") | O33: =IFERROR(VLOOKUP(O32,科目・教員!$A$2:$B$342,2,0),"") | Q33: =IFERROR(VLOOKUP(Q32,科目・教員!$A$2:$B$342,2,0),"") | S33: =IFERROR(VLOOKUP(S32,科目・教員!$A$2:$B$342,2,0),"")
B34: 使用教室 | C34: =VLOOKUP($C27,'2026年度(1年後期)'!$B$5:$N$207,COLUMN('2026年度(1年後期)'!$E$5)+1,0)&"" -> 101 | E34: =VLOOKUP($C27,'2026年度(2年後期)'!$B$5:$N$207,COLUMN('2026年度(2年後期)'!$E$5)+1,0)&"" | G34: =VLOOKUP($C27,'2026年度(3年後期)'!$B$5:$N$207,COLUMN('2026年度(3年後期)'!$E$5)+1,0)&"" -> 母性:201 | I34: =VLOOKUP($C27,'2026年度(4年後期)'!$B$5:$N$206,COLUMN('2026年度(4年後期)'!$E$5)+1,0)&"" | K34: =VLOOKUP($C27,'2026年度(助産後期)'!$B$5:$N$207,COLUMN('2026年度(助産後期)'!$E$5)+1,0)&"" | M34: =VLOOKUP($C27,'2026年度(M1後期)'!$B$5:$N$207,COLUMN('2026年度(M1後期)'!$E$5)+1,0)&"" | O34: =VLOOKUP($C27,'2026年度(M2後期)'!$B$5:$N$207,COLUMN('2026年度(M2後期)'!$E$5)+1,0)&"" | Q34: =VLOOKUP($C27,'2026年度(D1後期)'!$B$5:$N$207,COLUMN('2026年度(D1後期)'!$E$5)+1,0)&"" | S34: =VLOOKUP($C27,'2026年度(D23後期)'!$B$5:$N$207,COLUMN('2026年度(D23後期)'!$E$5)+1,0)&""
B35: 備 考
A36: 昼休み（12：30～13：30） | B36: 活動名 | Z36: =A36 -> 昼休み（12：30～13：30） | AM36: 母性看護学実習（自主練）
B37: 責任者
B38: 使用教室
B39: 備 考
A40: ３時限（13：30～15：00） | B40: 科目名 | C40: =VLOOKUP($C27,'2026年度(1年後期)'!$B$5:$N$207,COLUMN('2026年度(1年後期)'!$G$5),0)&"" -> 人間と教育 | E40: =VLOOKUP($C27,'2026年度(2年後期)'!$B$5:$N$207,COLUMN('2026年度(2年後期)'!$G$5),0)&"" -> 基礎看護学実習Ⅱ | G40: =VLOOKUP($C27,'2026年度(3年後期)'!$B$5:$N$207,COLUMN('2026年度(3年後期)'!$G$5),0)&"" -> 領域別実習 | I40: =VLOOKUP($C27,'2026年度(4年後期)'!$B$5:$N$206,COLUMN('2026年度(4年後期)'!$G$5),0)&"" | K40: =VLOOKUP($C27,'2026年度(助産後期)'!$B$5:$N$207,COLUMN('2026年度(助産後期)'!$G$5),0)&"" -> 地域母子保健（藤田先生） | M40: =VLOOKUP($C27,'2026年度(M1後期)'!$B$5:$N$207,COLUMN('2026年度(M1後期)'!$G$5),0)&"" -> 成人看護学演習A-Ⅰ | O40: =VLOOKUP($C27,'2026年度(M2後期)'!$B$5:$N$207,COLUMN('2026年度(M2後期)'!$G$5),0)&"" -> 特別研究 | Q40: =VLOOKUP($C27,'2026年度(D1後期)'!$B$5:$N$207,COLUMN('2026年度(D1後期)'!$G$5),0)&"" | S40: =VLOOKUP($C27,'2026年度(D23後期)'!$B$5:$N$207,COLUMN('2026年度(D23後期)'!$G$5),0)&"" -> 特別研究 | V40: 3限 | Z40: =A40 -> ３時限（13：30～15：00） | AH40: 人間と教育 | AM40: 母性看護学実習（自主練） | AZ40: 地域母子保健 | BK40: D1坂口
...

Sheet 2027年1月
A1: 46388 | C1: １年 | E1: ２年 | G1: ３年 | I1: ４年 | K1: 助産 | M1: 研究課程部 Ｍ１ | O1: 研究課程部 Ｍ２ | Q1: 研究課程部 Ｄ１ | S1: 研究課程部 Ｄ２３ | U1: =A1 -> 46388 | V1: 授業外その他教室等管理スケジュール | AA1: １階 | AG1: ２階 | AW1: ３階 | BI1: ４階 | BN1: 体育棟 | BP1: 研修棟
C2: =A1 -> 46388 | U2: =C2 -> 46388 | AA2: 101 | AB2: 102 | AC2: 103 | AD2: 在宅実習室 | AE2: 成人実習室 | AF2: 講堂 | AG2: 201 | AH2: 202 | AI2: 203 | AJ2: 204 | AK2: 205 | AL2: 基礎実習室 | AM2: 母性・小児実習室 | AN2: 演習21 | AO2: 演習22 | AP2: 演習23 | AQ2: 演習24 | AR2: 演習25 | AS2: 演習26 | AT2: 演習27 | AU2: 演習28 | AV2: 演習29 | AW2: 301 | AX2: 302 | AY2: 303 | AZ2: 304 | BA2: 臨床１ | BB2: 臨床２ | BC2: LL1 | BD2: LL2 | BE2: 実験室 | BF2: 情報処理室 | BG2: 演習31 | BH2: 演習32 | BI2: セミナー室１ | BJ2: セミナー室２ | BK2: セミナー室3 | BL2: セミナー室4 | BM2: セミナー室5 | BN2: 大講義室 | BO2: アリーナ | BP2: 研修１ | BQ2: 研修３ | BR2: 研修４ | BS2: 研修５ | BT2: 研修６ | BU2: 研修７ | BV2: 視聴覚室
A3: １時限（09：20～10：50） | B3: 科目名 | C3: =VLOOKUP($C2,'2026年度(1年後期)'!$B$5:$N$207,COLUMN('2026年度(1年後期)'!$C$5),0)&"" | E3: =VLOOKUP($C2,'2026年度(2年後期)'!$B$5:$N$207,COLUMN('2026年度(2年後期)'!$C$5),0)&"" | G3: =VLOOKUP($C2,'2026年度(3年後期)'!$B$5:$N$207,COLUMN('2026年度(3年後期)'!$C$5),0)&"" | I3: =VLOOKUP($C2,'2026年度(4年後期)'!$B$5:$N$206,COLUMN('2026年度(4年後期)'!$C$5),0)&"" | K3: =VLOOKUP($C2,'2026年度(助産後期)'!$B$5:$N$207,COLUMN('2026年度(助産後期)'!$C$5),0)&"" | M3: =VLOOKUP($C2,'2026年度(M1後期)'!$B$5:$N$207,COLUMN('2026年度(M1後期)'!$C$5),0)&"" | O3: =VLOOKUP($C2,'2026年度(M2後期)'!$B$5:$N$207,COLUMN('2026年度(M2後期)'!$C$5),0)&"" | Q3: =VLOOKUP($C2,'2026年度(D1後期)'!$B$5:$N$207,COLUMN('2026年度(D1後期)'!$C$5),0)&"" | S3: =VLOOKUP($C2,'2026年度(D23後期)'!$B$5:$N$207,COLUMN('2026年度(D23後期)'!$C$5),0)&"" | Z3: =A3 -> １時限（09：20～10：50）
B4: 教 官 | C4: =IFERROR(VLOOKUP(C3,科目・教員!$A$2:$B$342,2,0),"") | E4: =IFERROR(VLOOKUP(E3,科目・教員!$A$2:$B$342,2,0),"") | G4: =IFERROR(VLOOKUP(G3,科目・教員!$A$2:$B$342,2,0),"") | I4: =IFERROR(VLOOKUP(I3,科目・教員!$A$2:$B$342,2,0),"") | K4: =IFERROR(VLOOKUP(K3,科目・教員!$A$2:$B$342,2,0),"") | M4: =IFERROR(VLOOKUP(M3,科目・教員!$A$2:$B$342,2,0),"") | O4: =IFERROR(VLOOKUP(O3,科目・教員!$A$2:$B$342,2,0),"") | Q4: =IFERROR(VLOOKUP(Q3,科目・教員!$A$2:$B$342,2,0),"") | S4: =IFERROR(VLOOKUP(S3,科目・教員!$A$2:$B$342,2,0),"")
B5: 使用教室 | C5: =VLOOKUP($C2,'2026年度(1年後期)'!$B$5:$N$207,COLUMN('2026年度(1年後期)'!$C$5)+1,0)&"" | E5: =VLOOKUP($C2,'2026年度(2年後期)'!$B$5:$N$207,COLUMN('2026年度(2年後期)'!$C$5)+1,0)&"" | G5: =VLOOKUP($C2,'2026年度(3年後期)'!$B$5:$N$207,COLUMN('2026年度(3年後期)'!$C$5)+1,0)&"" | I5: =VLOOKUP($C2,'2026年度(4年後期)'!$B$5:$N$206,COLUMN('2026年度(4年後期)'!$C$5)+1,0)&"" | K5: =VLOOKUP($C2,'2026年度(助産後期)'!$B$5:$N$207,COLUMN('2026年度(助産後期)'!$C$5)+1,0)&"" | M5: =VLOOKUP($C2,'2026年度(M1後期)'!$B$5:$N$207,COLUMN('2026年度(M1後期)'!$C$5)+1,0)&"" | O5: =VLOOKUP($C2,'2026年度(M2後期)'!$B$5:$N$207,COLUMN('2026年度(M2後期)'!$C$5)+1,0)&"" | Q5: =VLOOKUP($C2,'2026年度(D1後期)'!$B$5:$N$207,COLUMN('2026年度(D1後期)'!$C$5)+1,0)&"" | S5: =VLOOKUP($C2,'2026年度(D23後期)'!$B$5:$N$207,COLUMN('2026年度(D23後期)'!$C$5)+1,0)&""
B6: 備 考
A7: ２時限（11：00～12：30） | B7: 科目名 | C7: =VLOOKUP($C2,'2026年度(1年後期)'!$B$5:$N$207,COLUMN('2026年度(1年後期)'!$E$5),0)&"" | E7: =VLOOKUP($C2,'2026年度(2年後期)'!$B$5:$N$207,COLUMN('2026年度(2年後期)'!$E$5),0)&"" | G7: =VLOOKUP($C2,'2026年度(3年後期)'!$B$5:$N$207,COLUMN('2026年度(3年後期)'!$E$5),0)&"" | I7: =VLOOKUP($C2,'2026年度(4年後期)'!$B$5:$N$206,COLUMN('2026年度(4年後期)'!$E$5),0)&"" | K7: =VLOOKUP($C2,'2026年度(助産後期)'!$B$5:$N$207,COLUMN('2026年度(助産後期)'!$E$5),0)&"" | M7: =VLOOKUP($C2,'2026年度(M1後期)'!$B$5:$N$207,COLUMN('2026年度(M1後期)'!$E$5),0)&"" | O7: =VLOOKUP($C2,'2026年度(M2後期)'!$B$5:$N$207,COLUMN('2026年度(M2後期)'!$E$5),0)&"" | Q7: =VLOOKUP($C2,'2026年度(D1後期)'!$B$5:$N$207,COLUMN('2026年度(D1後期)'!$E$5),0)&"" | S7: =VLOOKUP($C2,'2026年度(D23後期)'!$B$5:$N$207,COLUMN('2026年度(D23後期)'!$E$5),0)&"" | Z7: =A7 -> ２時限（11：00～12：30）
